Workbook

Sheet MENU
B2: =id_team -> TEAM PEMENANGAN JF JILID 3 | I2: ="Hari ini: "&TEXT(TODAY(),"dd/mm/yyyy") -> Hari ini: 03/08/2026
B3: =id_calon -> JONI FAHAMSYAH
B4: =id_periode -> PERIODE 2026 S/D 2034
B6: ="APLIKASI DATABASE ANGGOTA • DESA "&id_desa -> APLIKASI DATABASE ANGGOTA • DESA SUKAKARYA
B8: ▌ MENU UTAMA | E8: ▌ RINGKASAN DATA
B9: ▶ INPUT / DATABASE ANGGOTA | E9: Total anggota terdata | F9: =COUNTA(DATABASE!$B$4:$B$2003) -> 52
B10: ▶ CARI DATA ANGGOTA | E10: Anggota berstatus Aktif | F10: =COUNTIF(DATABASE!$T$4:$T$2003,"Aktif") -> 52
B11: ▶ REKAP & ANALISA | E11: Laki-laki / Perempuan | F11: =COUNTIF(DATABASE!$E$4:$E$2003,"L")&" / "&COUNTIF(DATABASE!$E$4:$E$2003,"P") -> 0 / 0
B12: ▶ TARGET & CAPAIAN | E12: Jumlah kampung aktif | F12: =SUMPRODUCT((COUNTIF(DATABASE!$F$4:$F$2003,REFERENSI!$B$6:$B$45)>0)*(REFERENSI!$B$6:$B$45<>"")) -> 5
B13: ▶ VALIDASI DATA | E13: Jumlah RT tercakup | F13: =SUMPRODUCT((COUNTIF(DATABASE!$G$4:$G$2003,REFERENSI!$D$6:$D$45)>0)*(REFERENSI!$D$6:$D$45<>"")) -> 5
B14: ▶ CETAK DAFTAR / FORMULIR | E14: Rata-rata usia (tahun) | F14: =IFERROR(ROUND(AVERAGE(DATABASE!$R$4:$R$2003),0),"-") -> -
B15: ▶ CETAK KARTU ANGGOTA | E15: Total target (semua Kadus) | F15: =SUM(REFERENSI!$C$6:$C$45) -> 0
B16: ▶ CETAK DAFTAR HADIR | E16: Capaian terhadap target | F16: =IFERROR(COUNTA(DATABASE!$B$4:$B$2003)/SUM(REFERENSI!$C$6:$C$45),"-") -> -
B17: ▶ PROFIL & MEDIA KAMPANYE | E17: Data perlu diperbaiki | F17: =COUNT(DATABASE!$AA$4:$AA$2003) -> 52
B18: ▶ PENGATURAN KADUS / RT / JABATAN | E18: Sisa kapasitas baris | F18: =2000-COUNTA(DATABASE!$B$4:$B$2003) -> 1948
B19: ▶ PETUNJUK PENGGUNAAN
B21: ▌ JUMLAH ANGGOTA PER KAMPUNG
B22: KAMPUNG | E22: JUMLAH | F22: TARGET | G22: CAPAIAN
B23: =IFERROR(INDEX(daftar_kampung,1),"") -> Kp. Gamprit | E23: =IF($B23="","",COUNTIF(DATABASE!$F$4:$F$2003,$B23)) -> 18 | F23: =IF($B23="","",IFERROR(INDEX(REFERENSI!$C$6:$C$45,1),0)) -> 0 | G23: =IF(OR($B23="",$F23=0),"",$E23/$F23)
B24: =IFERROR(INDEX(daftar_kampung,2),"") -> Kp. Kuda Kuda | E24: =IF($B24="","",COUNTIF(DATABASE!$F$4:$F$2003,$B24)) -> 11 | F24: =IF($B24="","",IFERROR(INDEX(REFERENSI!$C$6:$C$45,2),0)) -> 0 | G24: =IF(OR($B24="",$F24=0),"",$E24/$F24)
B25: =IFERROR(INDEX(daftar_kampung,3),"") -> Kp. Wangkal | E25: =IF($B25="","",COUNTIF(DATABASE!$F$4:$F$2003,$B25)) -> 10 | F25: =IF($B25="","",IFERROR(INDEX(REFERENSI!$C$6:$C$45,3),0)) -> 0 | G25: =IF(OR($B25="",$F25=0),"",$E25/$F25)
B26: =IFERROR(INDEX(daftar_kampung,4),"") -> Kp. Tenjolaut | E26: =IF($B26="","",COUNTIF(DATABASE!$F$4:$F$2003,$B26)) -> 2 | F26: =IF($B26="","",IFERROR(INDEX(REFERENSI!$C$6:$C$45,4),0)) -> 0 | G26: =IF(OR($B26="",$F26=0),"",$E26/$F26)
B27: =IFERROR(INDEX(daftar_kampung,5),"") -> Kp. Putri Melintang | E27: =IF($B27="","",COUNTIF(DATABASE!$F$4:$F$2003,$B27)) -> 1 | F27: =IF($B27="","",IFERROR(INDEX(REFERENSI!$C$6:$C$45,5),0)) -> 0 | G27: =IF(OR($B27="",$F27=0),"",$E27/$F27)
B28: =IFERROR(INDEX(daftar_kampung,6),"") | E28: =IF($B28="","",COUNTIF(DATABASE!$F$4:$F$2003,$B28)) | F28: =IF($B28="","",IFERROR(INDEX(REFERENSI!$C$6:$C$45,6),0)) | G28: =IF(OR($B28="",$F28=0),"",$E28/$F28)
B29: =IFERROR(INDEX(daftar_kampung,7),"") | E29: =IF($B29="","",COUNTIF(DATABASE!$F$4:$F$2003,$B29)) | F29: =IF($B29="","",IFERROR(INDEX(REFERENSI!$C$6:$C$45,7),0)) | G29: =IF(OR($B29="",$F29=0),"",$E29/$F29)
B30: =IFERROR(INDEX(daftar_kampung,8),"") | E30: =IF($B30="","",COUNTIF(DATABASE!$F$4:$F$2003,$B30)) | F30: =IF($B30="","",IFERROR(INDEX(REFERENSI!$C$6:$C$45,8),0)) | G30: =IF(OR($B30="",$F30=0),"",$E30/$F30)
B31: =IFERROR(INDEX(daftar_kampung,9),"") | E31: =IF($B31="","",COUNTIF(DATABASE!$F$4:$F$2003,$B31)) | F31: =IF($B31="","",IFERROR(INDEX(REFERENSI!$C$6:$C$45,9),0)) | G31: =IF(OR($B31="",$F31=0),"",$E31/$F31)
B32: =IFERROR(INDEX(daftar_kampung,10),"") | E32: =IF($B32="","",COUNTIF(DATABASE!$F$4:$F$2003,$B32)) | F32: =IF($B32="","",IFERROR(INDEX(REFERENSI!$C$6:$C$45,10),0)) | G32: =IF(OR($B32="",$F32=0),"",$E32/$F32)
B33: =IFERROR(INDEX(daftar_kampung,11),"") | E33: =IF($B33="","",COUNTIF(DATABASE!$F$4:$F$2003,$B33)) | F33: =IF($B33="","",IFERROR(INDEX(REFERENSI!$C$6:$C$45,11),0)) | G33: =IF(OR($B33="",$F33=0),"",$E33/$F33)
B34: =IFERROR(INDEX(daftar_kampung,12),"") | E34: =IF($B34="","",COUNTIF(DATABASE!$F$4:$F$2003,$B34)) | F34: =IF($B34="","",IFERROR(INDEX(REFERENSI!$C$6:$C$45,12),0)) | G34: =IF(OR($B34="",$F34=0),"",$E34/$F34)
B35: TOTAL SEMUA KAMPUNG | E35: =COUNTA(DATABASE!$B$4:$B$2003) -> 52 | F35: =SUM(REFERENSI!$C$6:$C$45) -> 0 | G35: =IF($F35=0,"",$E35/$F35)
B36: Menampilkan 12 kampung pertama — rekap lengkap ada di sheet REKAP dan TARGET.
B38: Alur kerja: PENGATURAN → DATABASE (input) → VALIDASI (bersihkan) → REKAP / TARGET (pantau) → CETAK / KARTU / ABSENSI (formulir)
B39: Seluruh angka pada halaman ini dihitung otomatis dari sheet DATABASE. Simpan dengan Ctrl+S setiap selesai menginput.
B40: Sel berlatar kuning = boleh diisi/diubah. Sel abu-abu = rumus otomatis, jangan diketik manual.

Sheet DATABASE
A1: DATABASE ANGGOTA TEAM PEMENANGAN
A2: ◀ MENU | C2: Ketik pada baris kosong pertama. Kolom abu-abu (NO, KORWIL, USIA, KELOMPOK USIA) terisi otomatis — jangan diketik manual. | T2: TOTAL | U2: =COUNTA($B$4:$B$2003) -> 52 | V2: SISA BARIS | W2: =2000-COUNTA($B$4:$B$2003) -> 1948
A3: NO | B3: NAMA LENGKAP | C3: NIK KTP (16 digit) | D3: NO. KK (16 digit) | E3: L/P | F3: KAMPUNG | G3: RT | H3: RW | I3: ALAMAT | J3: NAMA RT | K3: NAMA RW | L3: NAMA KADUS | M3: KORWIL | N3: JABATAN | O3: NO. HP | P3: TPS | Q3: TGL LAHIR | R3: USIA | S3: KELOMPOK USIA | T3: STATUS | U3: TGL GABUNG | V3: PEREKRUT | W3: CATATAN | X3: KEY | Y3: MASALAH | Z3: IDX_CARI | AA3: IDX_MASALAH | AB3: KEY_KAMPUNG | AC3: IDX_CETAK | AD3: IDX_ABSEN | AE3: IDX_KARTU
A4: =IF($B4="","",COUNTA($B$4:$B4)) -> 1 | B4: GURU BADRI | F4: Kp. Tenjolaut | G4: 001 | H4: 001 | K4: Maska | L4: Kadus 1 | M4: =IF($F4="","",$F4&IF($G4="",""," - RT "&$G4&IF($H4="","","/"&$H4))) -> Kp. Tenjolaut - RT 001/001 | N4: Anggota | R4: =IF(OR($B4="",$Q4=""),"",DATEDIF($Q4,TODAY(),"Y")) | S4: =IF($R4="","",INDEX(usia_label,MATCH($R4,usia_min,1))) | T4: Aktif | W4: asli: Guru Badri Kp. Tenjolaut RT 001/001 | X4: =IF($M4="","",$M4&"#"&COUNTIF($M$4:$M4,$M4)) -> Kp. Tenjolaut - RT 001/001#1 | Y4: =IF($B4="","",IF($C4="","NIK kosong",IF(LEN($C4)<>16,"NIK bukan 16 digit",IF(COUNTIF($C$4:$C$2003,$C4&"*")>1,"NIK ganda",IF(AND($D4<>"",LEN($D4)<>16),"No. KK bukan 16 digit",IF(AND($F4="",$I4=""),"Alamat kosong",IF($N4="","Jabatan kosong",IF($O4="","No. HP kosong",IF(AND($R4<>"",$R4<17),"Usia di bawah 17",""))))))))) -> NIK kosong | Z4: =IF($B4="","",IF(AND(OR(CARI!$C$5="",ISNUMBER(SEARCH(CARI!$C$5,$B4&" "&$C4&" "&$D4&" "&$O4&" "&$I4&" "&$F4&" "&$J4&" "&$K4&" "&$L4&" "&$V4))),OR(CARI!$C$6="",$F4=CARI!$C$6),OR(CARI!$C$7="",$G4=CARI!$C$7),OR(CARI!$C$8="",$T4=CARI!$C$8)),MAX($Z$3:Z3)+1,"")) -> 1 | AA4: =IF($Y4="","",MAX($AA$3:AA3)+1) -> 1 | AB4: =IF($F4="","",$F4&"#"&COUNTIF($F$4:$F4,$F4)) -> Kp. Tenjolaut#1 | AC4: =IF($B4="","",IF(AND(OR(CETAK!$J$10="",$F4=CETAK!$J$10),OR(CETAK!$J$11="",$G4=CETAK!$J$11),OR(CETAK!$J$12="",$P4=CETAK!$J$12),OR(CETAK!$J$13="",$N4=CETAK!$J$13),OR(CETAK!$J$14="",$T4=CETAK!$J$14)),MAX($AC$3:AC3)+1,"")) -> 1 | AD4: =IF($B4="","",IF(AND(OR(ABSENSI!$H$10="",$F4=ABSENSI!$H$10),OR(ABSENSI!$H$11="",$G4=ABSENSI!$H$11),OR(ABSENSI!$H$12="",$P4=ABSENSI!$H$12)),MAX($AD$3:AD3)+1,"")) -> 1 | AE4: =IF($B4="","",IF(AND(OR(KARTU!$K$6="",$F4=KARTU!$K$6),OR(KARTU!$K$7="",$G4=KARTU!$K$7),OR(KARTU!$K$8="",$P4=KARTU!$K$8)),MAX($AE$3:AE3)+1,"")) -> 1
A5: =IF($B5="","",COUNTA($B$4:$B5)) -> 2 | B5: IDRUS KAMSENO | F5: Kp. Gamprit | M5: =IF($F5="","",$F5&IF($G5="",""," - RT "&$G5&IF($H5="","","/"&$H5))) -> Kp. Gamprit | N5: Ketua Team | R5: =IF(OR($B5="",$Q5=""),"",DATEDIF($Q5,TODAY(),"Y")) | S5: =IF($R5="","",INDEX(usia_label,MATCH($R5,usia_min,1))) | T5: Aktif | W5: asli: Idrus Kamseno Kp. Gamprit | X5: =IF($M5="","",$M5&"#"&COUNTIF($M$4:$M5,$M5)) -> Kp. Gamprit#1 | Y5: =IF($B5="","",IF($C5="","NIK kosong",IF(LEN($C5)<>16,"NIK bukan 16 digit",IF(COUNTIF($C$4:$C$2003,$C5&"*")>1,"NIK ganda",IF(AND($D5<>"",LEN($D5)<>16),"No. KK bukan 16 digit",IF(AND($F5="",$I5=""),"Alamat kosong",IF($N5="","Jabatan kosong",IF($O5="","No. HP kosong",IF(AND($R5<>"",$R5<17),"Usia di bawah 17",""))))))))) -> NIK kosong | Z5: =IF($B5="","",IF(AND(OR(CARI!$C$5="",ISNUMBER(SEARCH(CARI!$C$5,$B5&" "&$C5&" "&$D5&" "&$O5&" "&$I5&" "&$F5&" "&$J5&" "&$K5&" "&$L5&" "&$V5))),OR(CARI!$C$6="",$F5=CARI!$C$6),OR(CARI!$C$7="",$G5=CARI!$C$7),OR(CARI!$C$8="",$T5=CARI!$C$8)),MAX($Z$3:Z4)+1,"")) -> 2 | AA5: =IF($Y5="","",MAX($AA$3:AA4)+1) -> 2 | AB5: =IF($F5="","",$F5&"#"&COUNTIF($F$4:$F5,$F5)) -> Kp. Gamprit#1 | AC5: =IF($B5="","",IF(AND(OR(CETAK!$J$10="",$F5=CETAK!$J$10),OR(CETAK!$J$11="",$G5=CETAK!$J$11),OR(CETAK!$J$12="",$P5=CETAK!$J$12),OR(CETAK!$J$13="",$N5=CETAK!$J$13),OR(CETAK!$J$14="",$T5=CETAK!$J$14)),MAX($AC$3:AC4)+1,"")) -> 2 | AD5: =IF($B5="","",IF(AND(OR(ABSENSI!$H$10="",$F5=ABSENSI!$H$10),OR(ABSENSI!$H$11="",$G5=ABSENSI!$H$11),OR(ABSENSI!$H$12="",$P5=ABSENSI!$H$12)),MAX($AD$3:AD4)+1,"")) -> 2 | AE5: =IF($B5="","",IF(AND(OR(KARTU!$K$6="",$F5=KARTU!$K$6),OR(KARTU!$K$7="",$G5=KARTU!$K$7),OR(KARTU!$K$8="",$P5=KARTU!$K$8)),MAX($AE$3:AE4)+1,"")) -> 2
A6: =IF($B6="","",COUNTA($B$4:$B6)) -> 3 | B6: ALI IBRO MALISI | F6: Kp. Tenjolaut | M6: =IF($F6="","",$F6&IF($G6="",""," - RT "&$G6&IF($H6="","","/"&$H6))) -> Kp. Tenjolaut | N6: Anggota | R6: =IF(OR($B6="",$Q6=""),"",DATEDIF($Q6,TODAY(),"Y")) | S6: =IF($R6="","",INDEX(usia_label,MATCH($R6,usia_min,1))) | T6: Aktif | W6: asli: Ali Ibro Malisi Kp Tenjolaut | X6: =IF($M6="","",$M6&"#"&COUNTIF($M$4:$M6,$M6)) -> Kp. Tenjolaut#1 | Y6: =IF($B6="","",IF($C6="","NIK kosong",IF(LEN($C6)<>16,"NIK bukan 16 digit",IF(COUNTIF($C$4:$C$2003,$C6&"*")>1,"NIK ganda",IF(AND($D6<>"",LEN($D6)<>16),"No. KK bukan 16 digit",IF(AND($F6="",$I6=""),"Alamat kosong",IF($N6="","Jabatan kosong",IF($O6="","No. HP kosong",IF(AND($R6<>"",$R6<17),"Usia di bawah 17",""))))))))) -> NIK kosong | Z6: =IF($B6="","",IF(AND(OR(CARI!$C$5="",ISNUMBER(SEARCH(CARI!$C$5,$B6&" "&$C6&" "&$D6&" "&$O6&" "&$I6&" "&$F6&" "&$J6&" "&$K6&" "&$L6&" "&$V6))),OR(CARI!$C$6="",$F6=CARI!$C$6),OR(CARI!$C$7="",$G6=CARI!$C$7),OR(CARI!$C$8="",$T6=CARI!$C$8)),MAX($Z$3:Z5)+1,"")) -> 3 | AA6: =IF($Y6="","",MAX($AA$3:AA5)+1) -> 3 | AB6: =IF($F6="","",$F6&"#"&COUNTIF($F$4:$F6,$F6)) -> Kp. Tenjolaut#2 | AC6: =IF($B6="","",IF(AND(OR(CETAK!$J$10="",$F6=CETAK!$J$10),OR(CETAK!$J$11="",$G6=CETAK!$J$11),OR(CETAK!$J$12="",$P6=CETAK!$J$12),OR(CETAK!$J$13="",$N6=CETAK!$J$13),OR(CETAK!$J$14="",$T6=CETAK!$J$14)),MAX($AC$3:AC5)+1,"")) -> 3 | AD6: =IF($B6="","",IF(AND(OR(ABSENSI!$H$10="",$F6=ABSENSI!$H$10),OR(ABSENSI!$H$11="",$G6=ABSENSI!$H$11),OR(ABSENSI!$H$12="",$P6=ABSENSI!$H$12)),MAX($AD$3:AD5)+1,"")) -> 3 | AE6: =IF($B6="","",IF(AND(OR(KARTU!$K$6="",$F6=KARTU!$K$6),OR(KARTU!$K$7="",$G6=KARTU!$K$7),OR(KARTU!$K$8="",$P6=KARTU!$K$8)),MAX($AE$3:AE5)+1,"")) -> 3
A7: =IF($B7="","",COUNTA($B$4:$B7)) -> 4 | B7: MURDIN (BENGKUNG) | F7: Kp. Gamprit | M7: =IF($F7="","",$F7&IF($G7="",""," - RT "&$G7&IF($H7="","","/"&$H7))) -> Kp. Gamprit | N7: Anggota | R7: =IF(OR($B7="",$Q7=""),"",DATEDIF($Q7,TODAY(),"Y")) | S7: =IF($R7="","",INDEX(usia_label,MATCH($R7,usia_min,1))) | T7: Aktif | W7: asli: Murdin/bengkung gamprit | X7: =IF($M7="","",$M7&"#"&COUNTIF($M$4:$M7,$M7)) -> Kp. Gamprit#2 | Y7: =IF($B7="","",IF($C7="","NIK kosong",IF(LEN($C7)<>16,"NIK bukan 16 digit",IF(COUNTIF($C$4:$C$2003,$C7&"*")>1,"NIK ganda",IF(AND($D7<>"",LEN($D7)<>16),"No. KK bukan 16 digit",IF(AND($F7="",$I7=""),"Alamat kosong",IF($N7="","Jabatan kosong",IF($O7="","No. HP kosong",IF(AND($R7<>"",$R7<17),"Usia di bawah 17",""))))))))) -> NIK kosong | Z7: =IF($B7="","",IF(AND(OR(CARI!$C$5="",ISNUMBER(SEARCH(CARI!$C$5,$B7&" "&$C7&" "&$D7&" "&$O7&" "&$I7&" "&$F7&" "&$J7&" "&$K7&" "&$L7&" "&$V7))),OR(CARI!$C$6="",$F7=CARI!$C$6),OR(CARI!$C$7="",$G7=CARI!$C$7),OR(CARI!$C$8="",$T7=CARI!$C$8)),MAX($Z$3:Z6)+1,"")) -> 4 | AA7: =IF($Y7="","",MAX($AA$3:AA6)+1) -> 4 | AB7: =IF($F7="","",$F7&"#"&COUNTIF($F$4:$F7,$F7)) -> Kp. Gamprit#2 | AC7: =IF($B7="","",IF(AND(OR(CETAK!$J$10="",$F7=CETAK!$J$10),OR(CETAK!$J$11="",$G7=CETAK!$J$11),OR(CETAK!$J$12="",$P7=CETAK!$J$12),OR(CETAK!$J$13="",$N7=CETAK!$J$13),OR(CETAK!$J$14="",$T7=CETAK!$J$14)),MAX($AC$3:AC6)+1,"")) -> 4 | AD7: =IF($B7="","",IF(AND(OR(ABSENSI!$H$10="",$F7=ABSENSI!$H$10),OR(ABSENSI!$H$11="",$G7=ABSENSI!$H$11),OR(ABSENSI!$H$12="",$P7=ABSENSI!$H$12)),MAX($AD$3:AD6)+1,"")) -> 4 | AE7: =IF($B7="","",IF(AND(OR(KARTU!$K$6="",$F7=KARTU!$K$6),OR(KARTU!$K$7="",$G7=KARTU!$K$7),OR(KARTU!$K$8="",$P7=KARTU!$K$8)),MAX($AE$3:AE6)+1,"")) -> 4
A8: =IF($B8="","",COUNTA($B$4:$B8)) -> 5 | B8: RUSTADI | F8: Kp. Wangkal | M8: =IF($F8="","",$F8&IF($G8="",""," - RT "&$G8&IF($H8="","","/"&$H8))) -> Kp. Wangkal | N8: Anggota | R8: =IF(OR($B8="",$Q8=""),"",DATEDIF($Q8,TODAY(),"Y")) | S8: =IF($R8="","",INDEX(usia_label,MATCH($R8,usia_min,1))) | T8: Aktif | W8: asli: Rustadi kp wangkal | X8: =IF($M8="","",$M8&"#"&COUNTIF($M$4:$M8,$M8)) -> Kp. Wangkal#1 | Y8: =IF($B8="","",IF($C8="","NIK kosong",IF(LEN($C8)<>16,"NIK bukan 16 digit",IF(COUNTIF($C$4:$C$2003,$C8&"*")>1,"NIK ganda",IF(AND($D8<>"",LEN($D8)<>16),"No. KK bukan 16 digit",IF(AND($F8="",$I8=""),"Alamat kosong",IF($N8="","Jabatan kosong",IF($O8="","No. HP kosong",IF(AND($R8<>"",$R8<17),"Usia di bawah 17",""))))))))) -> NIK kosong | Z8: =IF($B8="","",IF(AND(OR(CARI!$C$5="",ISNUMBER(SEARCH(CARI!$C$5,$B8&" "&$C8&" "&$D8&" "&$O8&" "&$I8&" "&$F8&" "&$J8&" "&$K8&" "&$L8&" "&$V8))),OR(CARI!$C$6="",$F8=CARI!$C$6),OR(CARI!$C$7="",$G8=CARI!$C$7),OR(CARI!$C$8="",$T8=CARI!$C$8)),MAX($Z$3:Z7)+1,"")) -> 5 | AA8: =IF($Y8="","",MAX($AA$3:AA7)+1) -> 5 | AB8: =IF($F8="","",$F8&"#"&COUNTIF($F$4:$F8,$F8)) -> Kp. Wangkal#1 | AC8: =IF($B8="","",IF(AND(OR(CETAK!$J$10="",$F8=CETAK!$J$10),OR(CETAK!$J$11="",$G8=CETAK!$J$11),OR(CETAK!$J$12="",$P8=CETAK!$J$12),OR(CETAK!$J$13="",$N8=CETAK!$J$13),OR(CETAK!$J$14="",$T8=CETAK!$J$14)),MAX($AC$3:AC7)+1,"")) -> 5 | AD8: =IF($B8="","",IF(AND(OR(ABSENSI!$H$10="",$F8=ABSENSI!$H$10),OR(ABSENSI!$H$11="",$G8=ABSENSI!$H$11),OR(ABSENSI!$H$12="",$P8=ABSENSI!$H$12)),MAX($AD$3:AD7)+1,"")) -> 5 | AE8: =IF($B8="","",IF(AND(OR(KARTU!$K$6="",$F8=KARTU!$K$6),OR(KARTU!$K$7="",$G8=KARTU!$K$7),OR(KARTU!$K$8="",$P8=KARTU!$K$8)),MAX($AE$3:AE7)+1,"")) -> 5
A9: =IF($B9="","",COUNTA($B$4:$B9)) -> 6 | B9: ABDUL MANAN | F9: Kp. Kuda Kuda | M9: =IF($F9="","",$F9&IF($G9="",""," - RT "&$G9&IF($H9="","","/"&$H9))) -> Kp. Kuda Kuda | N9: Anggota | R9: =IF(OR($B9="",$Q9=""),"",DATEDIF($Q9,TODAY(),"Y")) | S9: =IF($R9="","",INDEX(usia_label,MATCH($R9,usia_min,1))) | T9: Aktif | W9: asli: Abdul manan kuda kuda | X9: =IF($M9="","",$M9&"#"&COUNTIF($M$4:$M9,$M9)) -> Kp. Kuda Kuda#1 | Y9: =IF($B9="","",IF($C9="","NIK kosong",IF(LEN($C9)<>16,"NIK bukan 16 digit",IF(COUNTIF($C$4:$C$2003,$C9&"*")>1,"NIK ganda",IF(AND($D9<>"",LEN($D9)<>16),"No. KK bukan 16 digit",IF(AND($F9="",$I9=""),"Alamat kosong",IF($N9="","Jabatan kosong",IF($O9="","No. HP kosong",IF(AND($R9<>"",$R9<17),"Usia di bawah 17",""))))))))) -> NIK kosong | Z9: =IF($B9="","",IF(AND(OR(CARI!$C$5="",ISNUMBER(SEARCH(CARI!$C$5,$B9&" "&$C9&" "&$D9&" "&$O9&" "&$I9&" "&$F9&" "&$J9&" "&$K9&" "&$L9&" "&$V9))),OR(CARI!$C$6="",$F9=CARI!$C$6),OR(CARI!$C$7="",$G9=CARI!$C$7),OR(CARI!$C$8="",$T9=CARI!$C$8)),MAX($Z$3:Z8)+1,"")) -> 6 | AA9: =IF($Y9="","",MAX($AA$3:AA8)+1) -> 6 | AB9: =IF($F9="","",$F9&"#"&COUNTIF($F$4:$F9,$F9)) -> Kp. Kuda Kuda#1 | AC9: =IF($B9="","",IF(AND(OR(CETAK!$J$10="",$F9=CETAK!$J$10),OR(CETAK!$J$11="",$G9=CETAK!$J$11),OR(CETAK!$J$12="",$P9=CETAK!$J$12),OR(CETAK!$J$13="",$N9=CETAK!$J$13),OR(CETAK!$J$14="",$T9=CETAK!$J$14)),MAX($AC$3:AC8)+1,"")) -> 6 | AD9: =IF($B9="","",IF(AND(OR(ABSENSI!$H$10="",$F9=ABSENSI!$H$10),OR(ABSENSI!$H$11="",$G9=ABSENSI!$H$11),OR(ABSENSI!$H$12="",$P9=ABSENSI!$H$12)),MAX($AD$3:AD8)+1,"")) -> 6 | AE9: =IF($B9="","",IF(AND(OR(KARTU!$K$6="",$F9=KARTU!$K$6),OR(KARTU!$K$7="",$G9=KARTU!$K$7),OR(KARTU!$K$8="",$P9=KARTU!$K$8)),MAX($AE$3:AE8)+1,"")) -> 6
A10: =IF($B10="","",COUNTA($B$4:$B10)) -> 7 | B10: IJAH | F10: Kp. Putri Melintang | M10: =IF($F10="","",$F10&IF($G10="",""," - RT "&$G10&IF($H10="","","/"&$H10))) -> Kp. Putri Melintang | N10: Anggota | R10: =IF(OR($B10="",$Q10=""),"",DATEDIF($Q10,TODAY(),"Y")) | S10: =IF($R10="","",INDEX(usia_label,MATCH($R10,usia_min,1))) | T10: Aktif | W10: asli: Ijah mmh putri melintang | X10: =IF($M10="","",$M10&"#"&COUNTIF($M$4:$M10,$M10)) -> Kp. Putri Melintang#1 | Y10: =IF($B10="","",IF($C10="","NIK kosong",IF(LEN($C10)<>16,"NIK bukan 16 digit",IF(COUNTIF($C$4:$C$2003,$C10&"*")>1,"NIK ganda",IF(AND($D10<>"",LEN($D10)<>16),"No. KK bukan 16 digit",IF(AND($F10="",$I10=""),"Alamat kosong",IF($N10="","Jabatan kosong",IF($O10="","No. HP kosong",IF(AND($R10<>"",$R10<17),"Usia di bawah 17",""))))))))) -> NIK kosong | Z10: =IF($B10="","",IF(AND(OR(CARI!$C$5="",ISNUMBER(SEARCH(CARI!$C$5,$B10&" "&$C10&" "&$D10&" "&$O10&" "&$I10&" "&$F10&" "&$J10&" "&$K10&" "&$L10&" "&$V10))),OR(CARI!$C$6="",$F10=CARI!$C$6),OR(CARI!$C$7="",$G10=CARI!$C$7),OR(CARI!$C$8="",$T10=CARI!$C$8)),MAX($Z$3:Z9)+1,"")) -> 7 | AA10: =IF($Y10="","",MAX($AA$3:AA9)+1) -> 7 | AB10: =IF($F10="","",$F10&"#"&COUNTIF($F$4:$F10,$F10)) -> Kp. Putri Melintang#1 | AC10: =IF($B10="","",IF(AND(OR(CETAK!$J$10="",$F10=CETAK!$J$10),OR(CETAK!$J$11="",$G10=CETAK!$J$11),OR(CETAK!$J$12="",$P10=CETAK!$J$12),OR(CETAK!$J$13="",$N10=CETAK!$J$13),OR(CETAK!$J$14="",$T10=CETAK!$J$14)),MAX($AC$3:AC9)+1,"")) -> 7 | AD10: =IF($B10="","",IF(AND(OR(ABSENSI!$H$10="",$F10=ABSENSI!$H$10),OR(ABSENSI!$H$11="",$G10=ABSENSI!$H$11),OR(ABSENSI!$H$12="",$P10=ABSENSI!$H$12)),MAX($AD$3:AD9)+1,"")) -> 7 | AE10: =IF($B10="","",IF(AND(OR(KARTU!$K$6="",$F10=KARTU!$K$6),OR(KARTU!$K$7="",$G10=KARTU!$K$7),OR(KARTU!$K$8="",$P10=KARTU!$K$8)),MAX($AE$3:AE9)+1,"")) -> 7
A11: =IF($B11="","",COUNTA($B$4:$B11)) -> 8 | B11: JEBAG | F11: Kp. Kuda Kuda | G11: 001 | H11: 003 | K11: Sutejo | L11: Kadus 2 | M11: =IF($F11="","",$F11&IF($G11="",""," - RT "&$G11&IF($H11="","","/"&$H11))) -> Kp. Kuda Kuda - RT 001/003 | N11: Anggota | R11: =IF(OR($B11="",$Q11=""),"",DATEDIF($Q11,TODAY(),"Y")) | S11: =IF($R11="","",INDEX(usia_label,MATCH($R11,usia_min,1))) | T11: Aktif | W11: asli: Jebag kuda kuda 01/03 | X11: =IF($M11="","",$M11&"#"&COUNTIF($M$4:$M11,$M11)) -> Kp. Kuda Kuda - RT 001/003#1 | Y11: =IF($B11="","",IF($C11="","NIK kosong",IF(LEN($C11)<>16,"NIK bukan 16 digit",IF(COUNTIF($C$4:$C$2003,$C11&"*")>1,"NIK ganda",IF(AND($D11<>"",LEN($D11)<>16),"No. KK bukan 16 digit",IF(AND($F11="",$I11=""),"Alamat kosong",IF($N11="","Jabatan kosong",IF($O11="","No. HP kosong",IF(AND($R11<>"",$R11<17),"Usia di bawah 17",""))))))))) -> NIK kosong | Z11: =IF($B11="","",IF(AND(OR(CARI!$C$5="",ISNUMBER(SEARCH(CARI!$C$5,$B11&" "&$C11&" "&$D11&" "&$O11&" "&$I11&" "&$F11&" "&$J11&" "&$K11&" "&$L11&" "&$V11))),OR(CARI!$C$6="",$F11=CARI!$C$6),OR(CARI!$C$7="",$G11=CARI!$C$7),OR(CARI!$C$8="",$T11=CARI!$C$8)),MAX($Z$3:Z10)+1,"")) -> 8 | AA11: =IF($Y11="","",MAX($AA$3:AA10)+1) -> 8 | AB11: =IF($F11="","",$F11&"#"&COUNTIF($F$4:$F11,$F11)) -> Kp. Kuda Kuda#2 | AC11: =IF($B11="","",IF(AND(OR(CETAK!$J$10="",$F11=CETAK!$J$10),OR(CETAK!$J$11="",$G11=CETAK!$J$11),OR(CETAK!$J$12="",$P11=CETAK!$J$12),OR(CETAK!$J$13="",$N11=CETAK!$J$13),OR(CETAK!$J$14="",$T11=CETAK!$J$14)),MAX($AC$3:AC10)+1,"")) -> 8 | AD11: =IF($B11="","",IF(AND(OR(ABSENSI!$H$10="",$F11=ABSENSI!$H$10),OR(ABSENSI!$H$11="",$G11=ABSENSI!$H$11),OR(ABSENSI!$H$12="",$P11=ABSENSI!$H$12)),MAX($AD$3:AD10)+1,"")) -> 8 | AE11: =IF($B11="","",IF(AND(OR(KARTU!$K$6="",$F11=KARTU!$K$6),OR(KARTU!$K$7="",$G11=KARTU!$K$7),OR(KARTU!$K$8="",$P11=KARTU!$K$8)),MAX($AE$3:AE10)+1,"")) -> 8
A12: =IF($B12="","",COUNTA($B$4:$B12)) -> 9 | B12: DONY | F12: Kp. Gamprit | M12: =IF($F12="","",$F12&IF($G12="",""," - RT "&$G12&IF($H12="","","/"&$H12))) -> Kp. Gamprit | N12: Anggota | R12: =IF(OR($B12="",$Q12=""),"",DATEDIF($Q12,TODAY(),"Y")) | S12: =IF($R12="","",INDEX(usia_label,MATCH($R12,usia_min,1))) | T12: Aktif | W12: asli: Dony gamprit | X12: =IF($M12="","",$M12&"#"&COUNTIF($M$4:$M12,$M12)) -> Kp. Gamprit#3 | Y12: =IF($B12="","",IF($C12="","NIK kosong",IF(LEN($C12)<>16,"NIK bukan 16 digit",IF(COUNTIF($C$4:$C$2003,$C12&"*")>1,"NIK ganda",IF(AND($D12<>"",LEN($D12)<>16),"No. KK bukan 16 digit",IF(AND($F12="",$I12=""),"Alamat kosong",IF($N12="","Jabatan kosong",IF($O12="","No. HP kosong",IF(AND($R12<>"",$R12<17),"Usia di bawah 17",""))))))))) -> NIK kosong | Z12: =IF($B12="","",IF(AND(OR(CARI!$C$5="",ISNUMBER(SEARCH(CARI!$C$5,$B12&" "&$C12&" "&$D12&" "&$O12&" "&$I12&" "&$F12&" "&$J12&" "&$K12&" "&$L12&" "&$V12))),OR(CARI!$C$6="",$F12=CARI!$C$6),OR(CARI!$C$7="",$G12=CARI!$C$7),OR(CARI!$C$8="",$T12=CARI!$C$8)),MAX($Z$3:Z11)+1,"")) -> 9 | AA12: =IF($Y12="","",MAX($AA$3:AA11)+1) -> 9 | AB12: =IF($F12="","",$F12&"#"&COUNTIF($F$4:$F12,$F12)) -> Kp. Gamprit#3 | AC12: =IF($B12="","",IF(AND(OR(CETAK!$J$10="",$F12=CETAK!$J$10),OR(CETAK!$J$11="",$G12=CETAK!$J$11),OR(CETAK!$J$12="",$P12=CETAK!$J$12),OR(CETAK!$J$13="",$N12=CETAK!$J$13),OR(CETAK!$J$14="",$T12=CETAK!$J$14)),MAX($AC$3:AC11)+1,"")) -> 9 | AD12: =IF($B12="","",IF(AND(OR(ABSENSI!$H$10="",$F12=ABSENSI!$H$10),OR(ABSENSI!$H$11="",$G12=ABSENSI!$H$11),OR(ABSENSI!$H$12="",$P12=ABSENSI!$H$12)),MAX($AD$3:AD11)+1,"")) -> 9 | AE12: =IF($B12="","",IF(AND(OR(KARTU!$K$6="",$F12=KARTU!$K$6),OR(KARTU!$K$7="",$G12=KARTU!$K$7),OR(KARTU!$K$8="",$P12=KARTU!$K$8)),MAX($AE$3:AE11)+1,"")) -> 9
A13: =IF($B13="","",COUNTA($B$4:$B13)) -> 10 | B13: WAWAN | F13: Kp. Kuda Kuda | G13: 001 | H13: 004 | K13: Ilyas | L13: Kadus 2 | M13: =IF($F13="","",$F13&IF($G13="",""," - RT "&$G13&IF($H13="","","/"&$H13))) -> Kp. Kuda Kuda - RT 001/004 | N13: Anggota | R13: =IF(OR($B13="",$Q13=""),"",DATEDIF($Q13,TODAY(),"Y")) | S13: =IF($R13="","",INDEX(usia_label,MATCH($R13,usia_min,1))) | T13: Aktif | W13: asli: Wawan kuda kuda Rt 01/04 | X13: =IF($M13="","",$M13&"#"&COUNTIF($M$4:$M13,$M13)) -> Kp. Kuda Kuda - RT 001/004#1 | Y13: =IF($B13="","",IF($C13="","NIK kosong",IF(LEN($C13)<>16,"NIK bukan 16 digit",IF(COUNTIF($C$4:$C$2003,$C13&"*")>1,"NIK ganda",IF(AND($D13<>"",LEN($D13)<>16),"No. KK bukan 16 digit",IF(AND($F13="",$I13=""),"Alamat kosong",IF($N13="","Jabatan kosong",IF($O13="","No. HP kosong",IF(AND($R13<>"",$R13<17),"Usia di bawah 17",""))))))))) -> NIK kosong | Z13: =IF($B13="","",IF(AND(OR(CARI!$C$5="",ISNUMBER(SEARCH(CARI!$C$5,$B13&" "&$C13&" "&$D13&" "&$O13&" "&$I13&" "&$F13&" "&$J13&" "&$K13&" "&$L13&" "&$V13))),OR(CARI!$C$6="",$F13=CARI!$C$6),OR(CARI!$C$7="",$G13=CARI!$C$7),OR(CARI!$C$8="",$T13=CARI!$C$8)),MAX($Z$3:Z12)+1,"")) -> 10 | AA13: =IF($Y13="","",MAX($AA$3:AA12)+1) -> 10 | AB13: =IF($F13="","",$F13&"#"&COUNTIF($F$4:$F13,$F13)) -> Kp. Kuda Kuda#3 | AC13: =IF($B13="","",IF(AND(OR(CETAK!$J$10="",$F13=CETAK!$J$10),OR(CETAK!$J$11="",$G13=CETAK!$J$11),OR(CETAK!$J$12="",$P13=CETAK!$J$12),OR(CETAK!$J$13="",$N13=CETAK!$J$13),OR(CETAK!$J$14="",$T13=CETAK!$J$14)),MAX($AC$3:AC12)+1,"")) -> 10 | AD13: =IF($B13="","",IF(AND(OR(ABSENSI!$H$10="",$F13=ABSENSI!$H$10),OR(ABSENSI!$H$11="",$G13=ABSENSI!$H$11),OR(ABSENSI!$H$12="",$P13=ABSENSI!$H$12)),MAX($AD$3:AD12)+1,"")) -> 10 | AE13: =IF($B13="","",IF(AND(OR(KARTU!$K$6="",$F13=KARTU!$K$6),OR(KARTU!$K$7="",$G13=KARTU!$K$7),OR(KARTU!$K$8="",$P13=KARTU!$K$8)),MAX($AE$3:AE12)+1,"")) -> 10
A14: =IF($B14="","",COUNTA($B$4:$B14)) -> 11 | B14: MAS DENI | G14: 001 | H14: 004 | K14: Ilyas | L14: Kadus 2 | M14: =IF($F14="","",$F14&IF($G14="",""," - RT "&$G14&IF($H14="","","/"&$H14))) | N14: Anggota | R14: =IF(OR($B14="",$Q14=""),"",DATEDIF($Q14,TODAY(),"Y")) | S14: =IF($R14="","",INDEX(usia_label,MATCH($R14,usia_min,1))) | T14: Aktif | W14: asli: Mas Deni RT 01/04 | X14: =IF($M14="","",$M14&"#"&COUNTIF($M$4:$M14,$M14)) | Y14: =IF($B14="","",IF($C14="","NIK kosong",IF(LEN($C14)<>16,"NIK bukan 16 digit",IF(COUNTIF($C$4:$C$2003,$C14&"*")>1,"NIK ganda",IF(AND($D14<>"",LEN($D14)<>16),"No. KK bukan 16 digit",IF(AND($F14="",$I14=""),"Alamat kosong",IF($N14="","Jabatan kosong",IF($O14="","No. HP kosong",IF(AND($R14<>"",$R14<17),"Usia di bawah 17",""))))))))) -> NIK kosong | Z14: =IF($B14="","",IF(AND(OR(CARI!$C$5="",ISNUMBER(SEARCH(CARI!$C$5,$B14&" "&$C14&" "&$D14&" "&$O14&" "&$I14&" "&$F14&" "&$J14&" "&$K14&" "&$L14&" "&$V14))),OR(CARI!$C$6="",$F14=CARI!$C$6),OR(CARI!$C$7="",$G14=CARI!$C$7),OR(CARI!$C$8="",$T14=CARI!$C$8)),MAX($Z$3:Z13)+1,"")) -> 11 | AA14: =IF($Y14="","",MAX($AA$3:AA13)+1) -> 11 | AB14: =IF($F14="","",$F14&"#"&COUNTIF($F$4:$F14,$F14)) | AC14: =IF($B14="","",IF(AND(OR(CETAK!$J$10="",$F14=CETAK!$J$10),OR(CETAK!$J$11="",$G14=CETAK!$J$11),OR(CETAK!$J$12="",$P14=CETAK!$J$12),OR(CETAK!$J$13="",$N14=CETAK!$J$13),OR(CETAK!$J$14="",$T14=CETAK!$J$14)),MAX($AC$3:AC13)+1,"")) -> 11 | AD14: =IF($B14="","",IF(AND(OR(ABSENSI!$H$10="",$F14=ABSENSI!$H$10),OR(ABSENSI!$H$11="",$G14=ABSENSI!$H$11),OR(ABSENSI!$H$12="",$P14=ABSENSI!$H$12)),MAX($AD$3:AD13)+1,"")) -> 11 | AE14: =IF($B14="","",IF(AND(OR(KARTU!$K$6="",$F14=KARTU!$K$6),OR(KARTU!$K$7="",$G14=KARTU!$K$7),OR(KARTU!$K$8="",$P14=KARTU!$K$8)),MAX($AE$3:AE13)+1,"")) -> 11
A15: =IF($B15="","",COUNTA($B$4:$B15)) -> 12 | B15: HARIS | F15: Kp. Kuda Kuda | G15: 003 | H15: 001 | J15: Basir | K15: Maska | L15: Kadus 1 | M15: =IF($F15="","",$F15&IF($G15="",""," - RT "&$G15&IF($H15="","","/"&$H15))) -> Kp. Kuda Kuda - RT 003/001 | N15: Anggota | R15: =IF(OR($B15="",$Q15=""),"",DATEDIF($Q15,TODAY(),"Y")) | S15: =IF($R15="","",INDEX(usia_label,MATCH($R15,usia_min,1))) | T15: Aktif | W15: asli: Haris kuda kuda Rt003/001 Rt basir | X15: =IF($M15="","",$M15&"#"&COUNTIF($M$4:$M15,$M15)) -> Kp. Kuda Kuda - RT 003/001#1 | Y15: =IF($B15="","",IF($C15="","NIK kosong",IF(LEN($C15)<>16,"NIK bukan 16 digit",IF(COUNTIF($C$4:$C$2003,$C15&"*")>1,"NIK ganda",IF(AND($D15<>"",LEN($D15)<>16),"No. KK bukan 16 digit",IF(AND($F15="",$I15=""),"Alamat kosong",IF($N15="","Jabatan kosong",IF($O15="","No. HP kosong",IF(AND($R15<>"",$R15<17),"Usia di bawah 17",""))))))))) -> NIK kosong | Z15: =IF($B15="","",IF(AND(OR(CARI!$C$5="",ISNUMBER(SEARCH(CARI!$C$5,$B15&" "&$C15&" "&$D15&" "&$O15&" "&$I15&" "&$F15&" "&$J15&" "&$K15&" "&$L15&" "&$V15))),OR(CARI!$C$6="",$F15=CARI!$C$6),OR(CARI!$C$7="",$G15=CARI!$C$7),OR(CARI!$C$8="",$T15=CARI!$C$8)),MAX($Z$3:Z14)+1,"")) -> 12 | AA15: =IF($Y15="","",MAX($AA$3:AA14)+1) -> 12 | AB15: =IF($F15="","",$F15&"#"&COUNTIF($F$4:$F15,$F15)) -> Kp. Kuda Kuda#4 | AC15: =IF($B15="","",IF(AND(OR(CETAK!$J$10="",$F15=CETAK!$J$10),OR(CETAK!$J$11="",$G15=CETAK!$J$11),OR(CETAK!$J$12="",$P15=CETAK!$J$12),OR(CETAK!$J$13="",$N15=CETAK!$J$13),OR(CETAK!$J$14="",$T15=CETAK!$J$14)),MAX($AC$3:AC14)+1,"")) -> 12 | AD15: =IF($B15="","",IF(AND(OR(ABSENSI!$H$10="",$F15=ABSENSI!$H$10),OR(ABSENSI!$H$11="",$G15=ABSENSI!$H$11),OR(ABSENSI!$H$12="",$P15=ABSENSI!$H$12)),MAX($AD$3:AD14)+1,"")) -> 12 | AE15: =IF($B15="","",IF(AND(OR(KARTU!$K$6="",$F15=KARTU!$K$6),OR(KARTU!$K$7="",$G15=KARTU!$K$7),OR(KARTU!$K$8="",$P15=KARTU!$K$8)),MAX($AE$3:AE14)+1,"")) -> 12
A16: =IF($B16="","",COUNTA($B$4:$B16)) -> 13 | B16: NELIH | F16: Kp. Wangkal | G16: 004 | H16: 006 | K16: Saiman | L16: Kadus 3 | M16: =IF($F16="","",$F16&IF($G16="",""," - RT "&$G16&IF($H16="","","/"&$H16))) -> Kp. Wangkal - RT 004/006 | N16: Anggota | R16: =IF(OR($B16="",$Q16=""),"",DATEDIF($Q16,TODAY(),"Y")) | S16: =IF($R16="","",INDEX(usia_label,MATCH($R16,usia_min,1))) | T16: Aktif | W16: asli: Nelih wangkal 04/06 | X16: =IF($M16="","",$M16&"#"&COUNTIF($M$4:$M16,$M16)) -> Kp. Wangkal - RT 004/006#1 | Y16: =IF($B16="","",IF($C16="","NIK kosong",IF(LEN($C16)<>16,"NIK bukan 16 digit",IF(COUNTIF($C$4:$C$2003,$C16&"*")>1,"NIK ganda",IF(AND($D16<>"",LEN($D16)<>16),"No. KK bukan 16 digit",IF(AND($F16="",$I16=""),"Alamat kosong",IF($N16="","Jabatan kosong",IF($O16="","No. HP kosong",IF(AND($R16<>"",$R16<17),"Usia di bawah 17",""))))))))) -> NIK kosong | Z16: =IF($B16="","",IF(AND(OR(CARI!$C$5="",ISNUMBER(SEARCH(CARI!$C$5,$B16&" "&$C16&" "&$D16&" "&$O16&" "&$I16&" "&$F16&" "&$J16&" "&$K16&" "&$L16&" "&$V16))),OR(CARI!$C$6="",$F16=CARI!$C$6),OR(CARI!$C$7="",$G16=CARI!$C$7),OR(CARI!$C$8="",$T16=CARI!$C$8)),MAX($Z$3:Z15)+1,"")) -> 13 | AA16: =IF($Y16="","",MAX($AA$3:AA15)+1) -> 13 | AB16: =IF($F16="","",$F16&"#"&COUNTIF($F$4:$F16,$F16)) -> Kp. Wangkal#2 | AC16: =IF($B16="","",IF(AND(OR(CETAK!$J$10="",$F16=CETAK!$J$10),OR(CETAK!$J$11="",$G16=CETAK!$J$11),OR(CETAK!$J$12="",$P16=CETAK!$J$12),OR(CETAK!$J$13="",$N16=CETAK!$J$13),OR(CETAK!$J$14="",$T16=CETAK!$J$14)),MAX($AC$3:AC15)+1,"")) -> 13 | AD16: =IF($B16="","",IF(AND(OR(ABSENSI!$H$10="",$F16=ABSENSI!$H$10),OR(ABSENSI!$H$11="",$G16=ABSENSI!$H$11),OR(ABSENSI!$H$12="",$P16=ABSENSI!$H$12)),MAX($AD$3:AD15)+1,"")) -> 13 | AE16: =IF($B16="","",IF(AND(OR(KARTU!$K$6="",$F16=KARTU!$K$6),OR(KARTU!$K$7="",$G16=KARTU!$K$7),OR(KARTU!$K$8="",$P16=KARTU!$K$8)),MAX($AE$3:AE15)+1,"")) -> 13
A17: =IF($B17="","",COUNTA($B$4:$B17)) -> 14 | B17: RUDI | F17: Kp. Gamprit | G17: 003 | H17: 006 | J17: Wandy Suwandi | K17: Saiman | L17: Kadus 3 | M17: =IF($F17="","",$F17&IF($G17="",""," - RT "&$G17&IF($H17="","","/"&$H17))) -> Kp. Gamprit - RT 003/006 | N17: Anggota | R17: =IF(OR($B17="",$Q17=""),"",DATEDIF($Q17,TODAY(),"Y")) | S17: =IF($R17="","",INDEX(usia_label,MATCH($R17,usia_min,1))) | T17: Aktif | W17: asli: Rudi kp gamprit RT wandi | X17: =IF($M17="","",$M17&"#"&COUNTIF($M$4:$M17,$M17)) -> Kp. Gamprit - RT 003/006#1 | Y17: =IF($B17="","",IF($C17="","NIK kosong",IF(LEN($C17)<>16,"NIK bukan 16 digit",IF(COUNTIF($C$4:$C$2003,$C17&"*")>1,"NIK ganda",IF(AND($D17<>"",LEN($D17)<>16),"No. KK bukan 16 digit",IF(AND($F17="",$I17=""),"Alamat kosong",IF($N17="","Jabatan kosong",IF($O17="","No. HP kosong",IF(AND($R17<>"",$R17<17),"Usia di bawah 17",""))))))))) -> NIK kosong | Z17: =IF($B17="","",IF(AND(OR(CARI!$C$5="",ISNUMBER(SEARCH(CARI!$C$5,$B17&" "&$C17&" "&$D17&" "&$O17&" "&$I17&" "&$F17&" "&$J17&" "&$K17&" "&$L17&" "&$V17))),OR(CARI!$C$6="",$F17=CARI!$C$6),OR(CARI!$C$7="",$G17=CARI!$C$7),OR(CARI!$C$8="",$T17=CARI!$C$8)),MAX($Z$3:Z16)+1,"")) -> 14 | AA17: =IF($Y17="","",MAX($AA$3:AA16)+1) -> 14 | AB17: =IF($F17="","",$F17&"#"&COUNTIF($F$4:$F17,$F17)) -> Kp. Gamprit#4 | AC17: =IF($B17="","",IF(AND(OR(CETAK!$J$10="",$F17=CETAK!$J$10),OR(CETAK!$J$11="",$G17=CETAK!$J$11),OR(CETAK!$J$12="",$P17=CETAK!$J$12),OR(CETAK!$J$13="",$N17=CETAK!$J$13),OR(CETAK!$J$14="",$T17=CETAK!$J$14)),MAX($AC$3:AC16)+1,"")) -> 14 | AD17: =IF($B17="","",IF(AND(OR(ABSENSI!$H$10="",$F17=ABSENSI!$H$10),OR(ABSENSI!$H$11="",$G17=ABSENSI!$H$11),OR(ABSENSI!$H$12="",$P17=ABSENSI!$H$12)),MAX($AD$3:AD16)+1,"")) -> 14 | AE17: =IF($B17="","",IF(AND(OR(KARTU!$K$6="",$F17=KARTU!$K$6),OR(KARTU!$K$7="",$G17=KARTU!$K$7),OR(KARTU!$K$8="",$P17=KARTU!$K$8)),MAX($AE$3:AE16)+1,"")) -> 14
A18: =IF($B18="","",COUNTA($B$4:$B18)) -> 15 | B18: NIMAN | F18: Kp. Gamprit | G18: 002 | H18: 005 | K18: Niman | L18: Kadus 3 | M18: =IF($F18="","",$F18&IF($G18="",""," - RT "&$G18&IF($H18="","","/"&$H18))) -> Kp. Gamprit - RT 002/005 | N18: Ketua RW | R18: =IF(OR($B18="",$Q18=""),"",DATEDIF($Q18,TODAY(),"Y")) | S18: =IF($R18="","",INDEX(usia_label,MATCH($R18,usia_min,1))) | T18: Aktif | W18: asli: RK NIMAN RT 002/ RW 005 kp gamprit | X18: =IF($M18="","",$M18&"#"&COUNTIF($M$4:$M18,$M18)) -> Kp. Gamprit - RT 002/005#1 | Y18: =IF($B18="","",IF($C18="","NIK kosong",IF(LEN($C18)<>16,"NIK bukan 16 digit",IF(COUNTIF($C$4:$C$2003,$C18&"*")>1,"NIK ganda",IF(AND($D18<>"",LEN($D18)<>16),"No. KK bukan 16 digit",IF(AND($F18="",$I18=""),"Alamat kosong",IF($N18="","Jabatan kosong",IF($O18="","No. HP kosong",IF(AND($R18<>"",$R18<17),"Usia di bawah 17",""))))))))) -> NIK kosong | Z18: =IF($B18="","",IF(AND(OR(CARI!$C$5="",ISNUMBER(SEARCH(CARI!$C$5,$B18&" "&$C18&" "&$D18&" "&$O18&" "&$I18&" "&$F18&" "&$J18&" "&$K18&" "&$L18&" "&$V18))),OR(CARI!$C$6="",$F18=CARI!$C$6),OR(CARI!$C$7="",$G18=CARI!$C$7),OR(CARI!$C$8="",$T18=CARI!$C$8)),MAX($Z$3:Z17)+1,"")) -> 15 | AA18: =IF($Y18="","",MAX($AA$3:AA17)+1) -> 15 | AB18: =IF($F18="","",$F18&"#"&COUNTIF($F$4:$F18,$F18)) -> Kp. Gamprit#5 | AC18: =IF($B18="","",IF(AND(OR(CETAK!$J$10="",$F18=CETAK!$J$10),OR(CETAK!$J$11="",$G18=CETAK!$J$11),OR(CETAK!$J$12="",$P18=CETAK!$J$12),OR(CETAK!$J$13="",$N18=CETAK!$J$13),OR(CETAK!$J$14="",$T18=CETAK!$J$14)),MAX($AC$3:AC17)+1,"")) -> 15 | AD18: =IF($B18="","",IF(AND(OR(ABSENSI!$H$10="",$F18=ABSENSI!$H$10),OR(ABSENSI!$H$11="",$G18=ABSENSI!$H$11),OR(ABSENSI!$H$12="",$P18=ABSENSI!$H$12)),MAX($AD$3:AD17)+1,"")) -> 15 | AE18: =IF($B18="","",IF(AND(OR(KARTU!$K$6="",$F18=KARTU!$K$6),OR(KARTU!$K$7="",$G18=KARTU!$K$7),OR(KARTU!$K$8="",$P18=KARTU!$K$8)),MAX($AE$3:AE17)+1,"")) -> 15
A19: =IF($B19="","",COUNTA($B$4:$B19)) -> 16 | B19: RENALDI | F19: Kp. Gamprit | G19: 003 | H19: 006 | J19: Wandy Suwandi | K19: Saiman | L19: Kadus 3 | M19: =IF($F19="","",$F19&IF($G19="",""," - RT "&$G19&IF($H19="","","/"&$H19))) -> Kp. Gamprit - RT 003/006 | N19: Anggota | R19: =IF(OR($B19="",$Q19=""),"",DATEDIF($Q19,TODAY(),"Y")) | S19: =IF($R19="","",INDEX(usia_label,MATCH($R19,usia_min,1))) | T19: Aktif | W19: asli: Renaldi kp gamprit RT wandi | X19: =IF($M19="","",$M19&"#"&COUNTIF($M$4:$M19,$M19)) -> Kp. Gamprit - RT 003/006#2 | Y19: =IF($B19="","",IF($C19="","NIK kosong",IF(LEN($C19)<>16,"NIK bukan 16 digit",IF(COUNTIF($C$4:$C$2003,$C19&"*")>1,"NIK ganda",IF(AND($D19<>"",LEN($D19)<>16),"No. KK bukan 16 digit",IF(AND($F19="",$I19=""),"Alamat kosong",IF($N19="","Jabatan kosong",IF($O19="","No. HP kosong",IF(AND($R19<>"",$R19<17),"Usia di bawah 17",""))))))))) -> NIK kosong | Z19: =IF($B19="","",IF(AND(OR(CARI!$C$5="",ISNUMBER(SEARCH(CARI!$C$5,$B19&" "&$C19&" "&$D19&" "&$O19&" "&$I19&" "&$F19&" "&$J19&" "&$K19&" "&$L19&" "&$V19))),OR(CARI!$C$6="",$F19=CARI!$C$6),OR(CARI!$C$7="",$G19=CARI!$C$7),OR(CARI!$C$8="",$T19=CARI!$C$8)),MAX($Z$3:Z18)+1,"")) -> 16 | AA19: =IF($Y19="","",MAX($AA$3:AA18)+1) -> 16 | AB19: =IF($F19="","",$F19&"#"&COUNTIF($F$4:$F19,$F19)) -> Kp. Gamprit#6 | AC19: =IF($B19="","",IF(AND(OR(CETAK!$J$10="",$F19=CETAK!$J$10),OR(CETAK!$J$11="",$G19=CETAK!$J$11),OR(CETAK!$J$12="",$P19=CETAK!$J$12),OR(CETAK!$J$13="",$N19=CETAK!$J$13),OR(CETAK!$J$14="",$T19=CETAK!$J$14)),MAX($AC$3:AC18)+1,"")) -> 16 | AD19: =IF($B19="","",IF(AND(OR(ABSENSI!$H$10="",$F19=ABSENSI!$H$10),OR(ABSENSI!$H$11="",$G19=ABSENSI!$H$11),OR(ABSENSI!$H$12="",$P19=ABSENSI!$H$12)),MAX($AD$3:AD18)+1,"")) -> 16 | AE19: =IF($B19="","",IF(AND(OR(KARTU!$K$6="",$F19=KARTU!$K$6),OR(KARTU!$K$7="",$G19=KARTU!$K$7),OR(KARTU!$K$8="",$P19=KARTU!$K$8)),MAX($AE$3:AE18)+1,"")) -> 16
A20: =IF($B20="","",COUNTA($B$4:$B20)) -> 17 | B20: JAYA | F20: Kp. Wangkal | G20: 004 | H20: 006 | K20: Saiman | L20: Kadus 3 | M20: =IF($F20="","",$F20&IF($G20="",""," - RT "&$G20&IF($H20="","","/"&$H20))) -> Kp. Wangkal - RT 004/006 | N20: Anggota | R20: =IF(OR($B20="",$Q20=""),"",DATEDIF($Q20,TODAY(),"Y")) | S20: =IF($R20="","",INDEX(usia_label,MATCH($R20,usia_min,1))) | T20: Aktif | W20: asli: Jaya kp wangkal RT 04/06 | X20: =IF($M20="","",$M20&"#"&COUNTIF($M$4:$M20,$M20)) -> Kp. Wangkal - RT 004/006#2 | Y20: =IF($B20="","",IF($C20="","NIK kosong",IF(LEN($C20)<>16,"NIK bukan 16 digit",IF(COUNTIF($C$4:$C$2003,$C20&"*")>1,"NIK ganda",IF(AND($D20<>"",LEN($D20)<>16),"No. KK bukan 16 digit",IF(AND($F20="",$I20=""),"Alamat kosong",IF($N20="","Jabatan kosong",IF($O20="","No. HP kosong",IF(AND($R20<>"",$R20<17),"Usia di bawah 17",""))))))))) -> NIK kosong | Z20: =IF($B20="","",IF(AND(OR(CARI!$C$5="",ISNUMBER(SEARCH(CARI!$C$5,$B20&" "&$C20&" "&$D20&" "&$O20&" "&$I20&" "&$F20&" "&$J20&" "&$K20&" "&$L20&" "&$V20))),OR(CARI!$C$6="",$F20=CARI!$C$6),OR(CARI!$C$7="",$G20=CARI!$C$7),OR(CARI!$C$8="",$T20=CARI!$C$8)),MAX($Z$3:Z19)+1,"")) -> 17 | AA20: =IF($Y20="","",MAX($AA$3:AA19)+1) -> 17 | AB20: =IF($F20="","",$F20&"#"&COUNTIF($F$4:$F20,$F20)) -> Kp. Wangkal#3 | AC20: =IF($B20="","",IF(AND(OR(CETAK!$J$10="",$F20=CETAK!$J$10),OR(CETAK!$J$11="",$G20=CETAK!$J$11),OR(CETAK!$J$12="",$P20=CETAK!$J$12),OR(CETAK!$J$13="",$N20=CETAK!$J$13),OR(CETAK!$J$14="",$T20=CETAK!$J$14)),MAX($AC$3:AC19)+1,"")) -> 17 | AD20: =IF($B20="","",IF(AND(OR(ABSENSI!$H$10="",$F20=ABSENSI!$H$10),OR(ABSENSI!$H$11="",$G20=ABSENSI!$H$11),OR(ABSENSI!$H$12="",$P20=ABSENSI!$H$12)),MAX($AD$3:AD19)+1,"")) -> 17 | AE20: =IF($B20="","",IF(AND(OR(KARTU!$K$6="",$F20=KARTU!$K$6),OR(KARTU!$K$7="",$G20=KARTU!$K$7),OR(KARTU!$K$8="",$P20=KARTU!$K$8)),MAX($AE$3:AE19)+1,"")) -> 17
A21: =IF($B21="","",COUNTA($B$4:$B21)) -> 18 | B21: ADE RINO | F21: Kp. Gamprit | G21: 003 | H21: 006 | J21: Wandy Suwandi | K21: Saiman | L21: Kadus 3 | M21: =IF($F21="","",$F21&IF($G21="",""," - RT "&$G21&IF($H21="","","/"&$H21))) -> Kp. Gamprit - RT 003/006 | N21: Anggota | R21: =IF(OR($B21="",$Q21=""),"",DATEDIF($Q21,TODAY(),"Y")) | S21: =IF($R21="","",INDEX(usia_label,MATCH($R21,usia_min,1))) | T21: Aktif | W21: asli: Ade Rino kp gamprit RT wandi | X21: =IF($M21="","",$M21&"#"&COUNTIF($M$4:$M21,$M21)) -> Kp. Gamprit - RT 003/006#3 | Y21: =IF($B21="","",IF($C21="","NIK kosong",IF(LEN($C21)<>16,"NIK bukan 16 digit",IF(COUNTIF($C$4:$C$2003,$C21&"*")>1,"NIK ganda",IF(AND($D21<>"",LEN($D21)<>16),"No. KK bukan 16 digit",IF(AND($F21="",$I21=""),"Alamat kosong",IF($N21="","Jabatan kosong",IF($O21="","No. HP kosong",IF(AND($R21<>"",$R21<17),"Usia di bawah 17",""))))))))) -> NIK kosong | Z21: =IF($B21="","",IF(AND(OR(CARI!$C$5="",ISNUMBER(SEARCH(CARI!$C$5,$B21&" "&$C21&" "&$D21&" "&$O21&" "&$I21&" "&$F21&" "&$J21&" "&$K21&" "&$L21&" "&$V21))),OR(CARI!$C$6="",$F21=CARI!$C$6),OR(CARI!$C$7="",$G21=CARI!$C$7),OR(CARI!$C$8="",$T21=CARI!$C$8)),MAX($Z$3:Z20)+1,"")) -> 18 | AA21: =IF($Y21="","",MAX($AA$3:AA20)+1) -> 18 | AB21: =IF($F21="","",$F21&"#"&COUNTIF($F$4:$F21,$F21)) -> Kp. Gamprit#7 | AC21: =IF($B21="","",IF(AND(OR(CETAK!$J$10="",$F21=CETAK!$J$10),OR(CETAK!$J$11="",$G21=CETAK!$J$11),OR(CETAK!$J$12="",$P21=CETAK!$J$12),OR(CETAK!$J$13="",$N21=CETAK!$J$13),OR(CETAK!$J$14="",$T21=CETAK!$J$14)),MAX($AC$3:AC20)+1,"")) -> 18 | AD21: =IF($B21="","",IF(AND(OR(ABSENSI!$H$10="",$F21=ABSENSI!$H$10),OR(ABSENSI!$H$11="",$G21=ABSENSI!$H$11),OR(ABSENSI!$H$12="",$P21=ABSENSI!$H$12)),MAX($AD$3:AD20)+1,"")) -> 18 | AE21: =IF($B21="","",IF(AND(OR(KARTU!$K$6="",$F21=KARTU!$K$6),OR(KARTU!$K$7="",$G21=KARTU!$K$7),OR(KARTU!$K$8="",$P21=KARTU!$K$8)),MAX($AE$3:AE20)+1,"")) -> 18
A22: =IF($B22="","",COUNTA($B$4:$B22)) -> 19 | B22: WINDA | F22: Kp. Kuda Kuda | G22: 004 | J22: Onin | L22: Kadus 1 | M22: =IF($F22="","",$F22&IF($G22="",""," - RT "&$G22&IF($H22="","","/"&$H22))) -> Kp. Kuda Kuda - RT 004 | N22: Anggota | R22: =IF(OR($B22="",$Q22=""),"",DATEDIF($Q22,TODAY(),"Y")) | S22: =IF($R22="","",INDEX(usia_label,MATCH($R22,usia_min,1))) | T22: Aktif | W22: asli: Winda kp kuda kuda RT onin | X22: =IF($M22="","",$M22&"#"&COUNTIF($M$4:$M22,$M22)) -> Kp. Kuda Kuda - RT 004#1 | Y22: =IF($B22="","",IF($C22="","NIK kosong",IF(LEN($C22)<>16,"NIK bukan 16 digit",IF(COUNTIF($C$4:$C$2003,$C22&"*")>1,"NIK ganda",IF(AND($D22<>"",LEN($D22)<>16),"No. KK bukan 16 digit",IF(AND($F22="",$I22=""),"Alamat kosong",IF($N22="","Jabatan kosong",IF($O22="","No. HP kosong",IF(AND($R22<>"",$R22<17),"Usia di bawah 17",""))))))))) -> NIK kosong | Z22: =IF($B22="","",IF(AND(OR(CARI!$C$5="",ISNUMBER(SEARCH(CARI!$C$5,$B22&" "&$C22&" "&$D22&" "&$O22&" "&$I22&" "&$F22&" "&$J22&" "&$K22&" "&$L22&" "&$V22))),OR(CARI!$C$6="",$F22=CARI!$C$6),OR(CARI!$C$7="",$G22=CARI!$C$7),OR(CARI!$C$8="",$T22=CARI!$C$8)),MAX($Z$3:Z21)+1,"")) -> 19 | AA22: =IF($Y22="","",MAX($AA$3:AA21)+1) -> 19 | AB22: =IF($F22="","",$F22&"#"&COUNTIF($F$4:$F22,$F22)) -> Kp. Kuda Kuda#5 | AC22: =IF($B22="","",IF(AND(OR(CETAK!$J$10="",$F22=CETAK!$J$10),OR(CETAK!$J$11="",$G22=CETAK!$J$11),OR(CETAK!$J$12="",$P22=CETAK!$J$12),OR(CETAK!$J$13="",$N22=CETAK!$J$13),OR(CETAK!$J$14="",$T22=CETAK!$J$14)),MAX($AC$3:AC21)+1,"")) -> 19 | AD22: =IF($B22="","",IF(AND(OR(ABSENSI!$H$10="",$F22=ABSENSI!$H$10),OR(ABSENSI!$H$11="",$G22=ABSENSI!$H$11),OR(ABSENSI!$H$12="",$P22=ABSENSI!$H$12)),MAX($AD$3:AD21)+1,"")) -> 19 | AE22: =IF($B22="","",IF(AND(OR(KARTU!$K$6="",$F22=KARTU!$K$6),OR(KARTU!$K$7="",$G22=KARTU!$K$7),OR(KARTU!$K$8="",$P22=KARTU!$K$8)),MAX($AE$3:AE21)+1,"")) -> 19
A23: =IF($B23="","",COUNTA($B$4:$B23)) -> 20 | B23: HERMAN BOLON | F23: Kp. Gamprit | G23: 003 | H23: 006 | J23: Wandy Suwandi | K23: Saiman | L23: Kadus 3 | M23: =IF($F23="","",$F23&IF($G23="",""," - RT "&$G23&IF($H23="","","/"&$H23))) -> Kp. Gamprit - RT 003/006 | N23: Anggota | R23: =IF(OR($B23="",$Q23=""),"",DATEDIF($Q23,TODAY(),"Y")) | S23: =IF($R23="","",INDEX(usia_label,MATCH($R23,usia_min,1))) | T23: Aktif | W23: asli: Herman Bolon kp gamprit RT wandi | X23: =IF($M23="","",$M23&"#"&COUNTIF($M$4:$M23,$M23)) -> Kp. Gamprit - RT 003/006#4 | Y23: =IF($B23="","",IF($C23="","NIK kosong",IF(LEN($C23)<>16,"NIK bukan 16 digit",IF(COUNTIF($C$4:$C$2003,$C23&"*")>1,"NIK ganda",IF(AND($D23<>"",LEN($D23)<>16),"No. KK bukan 16 digit",IF(AND($F23="",$I23=""),"Alamat kosong",IF($N23="","Jabatan kosong",IF($O23="","No. HP kosong",IF(AND($R23<>"",$R23<17),"Usia di bawah 17",""))))))))) -> NIK kosong | Z23: =IF($B23="","",IF(AND(OR(CARI!$C$5="",ISNUMBER(SEARCH(CARI!$C$5,$B23&" "&$C23&" "&$D23&" "&$O23&" "&$I23&" "&$F23&" "&$J23&" "&$K23&" "&$L23&" "&$V23))),OR(CARI!$C$6="",$F23=CARI!$C$6),OR(CARI!$C$7="",$G23=CARI!$C$7),OR(CARI!$C$8="",$T23=CARI!$C$8)),MAX($Z$3:Z22)+1,"")) -> 20 | AA23: =IF($Y23="","",MAX($AA$3:AA22)+1) -> 20 | AB23: =IF($F23="","",$F23&"#"&COUNTIF($F$4:$F23,$F23)) -> Kp. Gamprit#8 | AC23: =IF($B23="","",IF(AND(OR(CETAK!$J$10="",$F23=CETAK!$J$10),OR(CETAK!$J$11="",$G23=CETAK!$J$11),OR(CETAK!$J$12="",$P23=CETAK!$J$12),OR(CETAK!$J$13="",$N23=CETAK!$J$13),OR(CETAK!$J$14="",$T23=CETAK!$J$14)),MAX($AC$3:AC22)+1,"")) -> 20 | AD23: =IF($B23="","",IF(AND(OR(ABSENSI!$H$10="",$F23=ABSENSI!$H$10),OR(ABSENSI!$H$11="",$G23=ABSENSI!$H$11),OR(ABSENSI!$H$12="",$P23=ABSENSI!$H$12)),MAX($AD$3:AD22)+1,"")) -> 20 | AE23: =IF($B23="","",IF(AND(OR(KARTU!$K$6="",$F23=KARTU!$K$6),OR(KARTU!$K$7="",$G23=KARTU!$K$7),OR(KARTU!$K$8="",$P23=KARTU!$K$8)),MAX($AE$3:AE22)+1,"")) -> 20
A24: =IF($B24="","",COUNTA($B$4:$B24)) -> 21 | B24: TASBIH (BODONG) | F24: Kp. Wangkal | G24: 004 | H24: 006 | J24: Nemin | K24: Saiman | L24: Kadus 3 | M24: =IF($F24="","",$F24&IF($G24="",""," - RT "&$G24&IF($H24="","","/"&$H24))) -> Kp. Wangkal - RT 004/006 | N24: Anggota | R24: =IF(OR($B24="",$Q24=""),"",DATEDIF($Q24,TODAY(),"Y")) | S24: =IF($R24="","",INDEX(usia_label,MATCH($R24,usia_min,1))) | T24: Aktif | W24: asli: Tasbih/bodong kp wangkal RT nemin | X24: =IF($M24="","",$M24&"#"&COUNTIF($M$4:$M24,$M24)) -> Kp. Wangkal - RT 004/006#3 | Y24: =IF($B24="","",IF($C24="","NIK kosong",IF(LEN($C24)<>16,"NIK bukan 16 digit",IF(COUNTIF($C$4:$C$2003,$C24&"*")>1,"NIK ganda",IF(AND($D24<>"",LEN($D24)<>16),"No. KK bukan 16 digit",IF(AND($F24="",$I24=""),"Alamat kosong",IF($N24="","Jabatan kosong",IF($O24="","No. HP kosong",IF(AND($R24<>"",$R24<17),"Usia di bawah 17",""))))))))) -> NIK kosong | Z24: =IF($B24="","",IF(AND(OR(CARI!$C$5="",ISNUMBER(SEARCH(CARI!$C$5,$B24&" "&$C24&" "&$D24&" "&$O24&" "&$I24&" "&$F24&" "&$J24&" "&$K24&" "&$L24&" "&$V24))),OR(CARI!$C$6="",$F24=CARI!$C$6),OR(CARI!$C$7="",$G24=CARI!$C$7),OR(CARI!$C$8="",$T24=CARI!$C$8)),MAX($Z$3:Z23)+1,"")) -> 21 | AA24: =IF($Y24="","",MAX($AA$3:AA23)+1) -> 21 | AB24: =IF($F24="","",$F24&"#"&COUNTIF($F$4:$F24,$F24)) -> Kp. Wangkal#4 | AC24: =IF($B24="","",IF(AND(OR(CETAK!$J$10="",$F24=CETAK!$J$10),OR(CETAK!$J$11="",$G24=CETAK!$J$11),OR(CETAK!$J$12="",$P24=CETAK!$J$12),OR(CETAK!$J$13="",$N24=CETAK!$J$13),OR(CETAK!$J$14="",$T24=CETAK!$J$14)),MAX($AC$3:AC23)+1,"")) -> 21 | AD24: =IF($B24="","",IF(AND(OR(ABSENSI!$H$10="",$F24=ABSENSI!$H$10),OR(ABSENSI!$H$11="",$G24=ABSENSI!$H$11),OR(ABSENSI!$H$12="",$P24=ABSENSI!$H$12)),MAX($AD$3:AD23)+1,"")) -> 21 | AE24: =IF($B24="","",IF(AND(OR(KARTU!$K$6="",$F24=KARTU!$K$6),OR(KARTU!$K$7="",$G24=KARTU!$K$7),OR(KARTU!$K$8="",$P24=KARTU!$K$8)),MAX($AE$3:AE23)+1,"")) -> 21
A25: =IF($B25="","",COUNTA($B$4:$B25)) -> 22 | B25: MARDI | F25: Kp. Wangkal | G25: 005 | H25: 006 | K25: Saiman | L25: Kadus 3 | M25: =IF($F25="","",$F25&IF($G25="",""," - RT "&$G25&IF($H25="","","/"&$H25))) -> Kp. Wangkal - RT 005/006 | N25: Anggota | R25: =IF(OR($B25="",$Q25=""),"",DATEDIF($Q25,TODAY(),"Y")) | S25: =IF($R25="","",INDEX(usia_label,MATCH($R25,usia_min,1))) | T25: Aktif | W25: asli: Mardi kp wangkal RT 05/06 | X25: =IF($M25="","",$M25&"#"&COUNTIF($M$4:$M25,$M25)) -> Kp. Wangkal - RT 005/006#1 | Y25: =IF($B25="","",IF($C25="","NIK kosong",IF(LEN($C25)<>16,"NIK bukan 16 digit",IF(COUNTIF($C$4:$C$2003,$C25&"*")>1,"NIK ganda",IF(AND($D25<>"",LEN($D25)<>16),"No. KK bukan 16 digit",IF(AND($F25="",$I25=""),"Alamat kosong",IF($N25="","Jabatan kosong",IF($O25="","No. HP kosong",IF(AND($R25<>"",$R25<17),"Usia di bawah 17",""))))))))) -> NIK kosong | Z25: =IF($B25="","",IF(AND(OR(CARI!$C$5="",ISNUMBER(SEARCH(CARI!$C$5,$B25&" "&$C25&" "&$D25&" "&$O25&" "&$I25&" "&$F25&" "&$J25&" "&$K25&" "&$L25&" "&$V25))),OR(CARI!$C$6="",$F25=CARI!$C$6),OR(CARI!$C$7="",$G25=CARI!$C$7),OR(CARI!$C$8="",$T25=CARI!$C$8)),MAX($Z$3:Z24)+1,"")) -> 22 | AA25: =IF($Y25="","",MAX($AA$3:AA24)+1) -> 22 | AB25: =IF($F25="","",$F25&"#"&COUNTIF($F$4:$F25,$F25)) -> Kp. Wangkal#5 | AC25: =IF($B25="","",IF(AND(OR(CETAK!$J$10="",$F25=CETAK!$J$10),OR(CETAK!$J$11="",$G25=CETAK!$J$11),OR(CETAK!$J$12="",$P25=CETAK!$J$12),OR(CETAK!$J$13="",$N25=CETAK!$J$13),OR(CETAK!$J$14="",$T25=CETAK!$J$14)),MAX($AC$3:AC24)+1,"")) -> 22 | AD25: =IF($B25="","",IF(AND(OR(ABSENSI!$H$10="",$F25=ABSENSI!$H$10),OR(ABSENSI!$H$11="",$G25=ABSENSI!$H$11),OR(ABSENSI!$H$12="",$P25=ABSENSI!$H$12)),MAX($AD$3:AD24)+1,"")) -> 22 | AE25: =IF($B25="","",IF(AND(OR(KARTU!$K$6="",$F25=KARTU!$K$6),OR(KARTU!$K$7="",$G25=KARTU!$K$7),OR(KARTU!$K$8="",$P25=KARTU!$K$8)),MAX($AE$3:AE24)+1,"")) -> 22
A26: =IF($B26="","",COUNTA($B$4:$B26)) -> 23 | B26: OTIH (AAL) | F26: Kp. Gamprit | G26: 003 | H26: 006 | J26: Wandy Suwandi | K26: Saiman | L26: Kadus 3 | M26: =IF($F26="","",$F26&IF($G26="",""," - RT "&$G26&IF($H26="","","/"&$H26))) -> Kp. Gamprit - RT 003/006 | N26: Anggota | R26: =IF(OR($B26="",$Q26=""),"",DATEDIF($Q26,TODAY(),"Y")) | S26: =IF($R26="","",INDEX(usia_label,MATCH($R26,usia_min,1))) | T26: Aktif | W26: asli: Otih/aal kp gamprit RT wandi | X26: =IF($M26="","",$M26&"#"&COUNTIF($M$4:$M26,$M26)) -> Kp. Gamprit - RT 003/006#5 | Y26: =IF($B26="","",IF($C26="","NIK kosong",IF(LEN($C26)<>16,"NIK bukan 16 digit",IF(COUNTIF($C$4:$C$2003,$C26&"*")>1,"NIK ganda",IF(AND($D26<>"",LEN($D26)<>16),"No. KK bukan 16 digit",IF(AND($F26="",$I26=""),"Alamat kosong",IF($N26="","Jabatan kosong",IF($O26="","No. HP kosong",IF(AND($R26<>"",$R26<17),"Usia di bawah 17",""))))))))) -> NIK kosong | Z26: =IF($B26="","",IF(AND(OR(CARI!$C$5="",ISNUMBER(SEARCH(CARI!$C$5,$B26&" "&$C26&" "&$D26&" "&$O26&" "&$I26&" "&$F26&" "&$J26&" "&$K26&" "&$L26&" "&$V26))),OR(CARI!$C$6="",$F26=CARI!$C$6),OR(CARI!$C$7="",$G26=CARI!$C$7),OR(CARI!$C$8="",$T26=CARI!$C$8)),MAX($Z$3:Z25)+1,"")) -> 23 | AA26: =IF($Y26="","",MAX($AA$3:AA25)+1) -> 23 | AB26: =IF($F26="","",$F26&"#"&COUNTIF($F$4:$F26,$F26)) -> Kp. Gamprit#9 | AC26: =IF($B26="","",IF(AND(OR(CETAK!$J$10="",$F26=CETAK!$J$10),OR(CETAK!$J$11="",$G26=CETAK!$J$11),OR(CETAK!$J$12="",$P26=CETAK!$J$12),OR(CETAK!$J$13="",$N26=CETAK!$J$13),OR(CETAK!$J$14="",$T26=CETAK!$J$14)),MAX($AC$3:AC25)+1,"")) -> 23 | AD26: =IF($B26="","",IF(AND(OR(ABSENSI!$H$10="",$F26=ABSENSI!$H$10),OR(ABSENSI!$H$11="",$G26=ABSENSI!$H$11),OR(ABSENSI!$H$12="",$P26=ABSENSI!$H$12)),MAX($AD$3:AD25)+1,"")) -> 23 | AE26: =IF($B26="","",IF(AND(OR(KARTU!$K$6="",$F26=KARTU!$K$6),OR(KARTU!$K$7="",$G26=KARTU!$K$7),OR(KARTU!$K$8="",$P26=KARTU!$K$8)),MAX($AE$3:AE25)+1,"")) -> 23
A27: =IF($B27="","",COUNTA($B$4:$B27)) -> 24 | B27: KANDI | F27: Kp. Gamprit | G27: 003 | H27: 006 | J27: Wandy Suwandi | K27: Saiman | L27: Kadus 3 | M27: =IF($F27="","",$F27&IF($G27="",""," - RT "&$G27&IF($H27="","","/"&$H27))) -> Kp. Gamprit - RT 003/006 | N27: Anggota | R27: =IF(OR($B27="",$Q27=""),"",DATEDIF($Q27,TODAY(),"Y")) | S27: =IF($R27="","",INDEX(usia_label,MATCH($R27,usia_min,1))) | T27: Aktif | W27: asli: Kandi gamprit RT wandi | X27: =IF($M27="","",$M27&"#"&COUNTIF($M$4:$M27,$M27)) -> Kp. Gamprit - RT 003/006#6 | Y27: =IF($B27="","",IF($C27="","NIK kosong",IF(LEN($C27)<>16,"NIK bukan 16 digit",IF(COUNTIF($C$4:$C$2003,$C27&"*")>1,"NIK ganda",IF(AND($D27<>"",LEN($D27)<>16),"No. KK bukan 16 digit",IF(AND($F27="",$I27=""),"Alamat kosong",IF($N27="","Jabatan kosong",IF($O27="","No. HP kosong",IF(AND($R27<>"",$R27<17),"Usia di bawah 17",""))))))))) -> NIK kosong | Z27: =IF($B27="","",IF(AND(OR(CARI!$C$5="",ISNUMBER(SEARCH(CARI!$C$5,$B27&" "&$C27&" "&$D27&" "&$O27&" "&$I27&" "&$F27&" "&$J27&" "&$K27&" "&$L27&" "&$V27))),OR(CARI!$C$6="",$F27=CARI!$C$6),OR(CARI!$C$7="",$G27=CARI!$C$7),OR(CARI!$C$8="",$T27=CARI!$C$8)),MAX($Z$3:Z26)+1,"")) -> 24 | AA27: =IF($Y27="","",MAX($AA$3:AA26)+1) -> 24 | AB27: =IF($F27="","",$F27&"#"&COUNTIF($F$4:$F27,$F27)) -> Kp. Gamprit#10 | AC27: =IF($B27="","",IF(AND(OR(CETAK!$J$10="",$F27=CETAK!$J$10),OR(CETAK!$J$11="",$G27=CETAK!$J$11),OR(CETAK!$J$12="",$P27=CETAK!$J$12),OR(CETAK!$J$13="",$N27=CETAK!$J$13),OR(CETAK!$J$14="",$T27=CETAK!$J$14)),MAX($AC$3:AC26)+1,"")) -> 24 | AD27: =IF($B27="","",IF(AND(OR(ABSENSI!$H$10="",$F27=ABSENSI!$H$10),OR(ABSENSI!$H$11="",$G27=ABSENSI!$H$11),OR(ABSENSI!$H$12="",$P27=ABSENSI!$H$12)),MAX($AD$3:AD26)+1,"")) -> 24 | AE27: =IF($B27="","",IF(AND(OR(KARTU!$K$6="",$F27=KARTU!$K$6),OR(KARTU!$K$7="",$G27=KARTU!$K$7),OR(KARTU!$K$8="",$P27=KARTU!$K$8)),MAX($AE$3:AE26)+1,"")) -> 24
A28: =IF($B28="","",COUNTA($B$4:$B28)) -> 25 | B28: EMIN (KOJEK) | F28: Kp. Wangkal | G28: 004 | H28: 006 | K28: Saiman | L28: Kadus 3 | M28: =IF($F28="","",$F28&IF($G28="",""," - RT "&$G28&IF($H28="","","/"&$H28))) -> Kp. Wangkal - RT 004/006 | N28: Anggota | R28: =IF(OR($B28="",$Q28=""),"",DATEDIF($Q28,TODAY(),"Y")) | S28: =IF($R28="","",INDEX(usia_label,MATCH($R28,usia_min,1))) | T28: Aktif | W28: asli: Emin/Kojek kp wangkal RT 04/06 | X28: =IF($M28="","",$M28&"#"&COUNTIF($M$4:$M28,$M28)) -> Kp. Wangkal - RT 004/006#4 | Y28: =IF($B28="","",IF($C28="","NIK kosong",IF(LEN($C28)<>16,"NIK bukan 16 digit",IF(COUNTIF($C$4:$C$2003,$C28&"*")>1,"NIK ganda",IF(AND($D28<>"",LEN($D28)<>16),"No. KK bukan 16 digit",IF(AND($F28="",$I28=""),"Alamat kosong",IF($N28="","Jabatan kosong",IF($O28="","No. HP kosong",IF(AND($R28<>"",$R28<17),"Usia di bawah 17",""))))))))) -> NIK kosong | Z28: =IF($B28="","",IF(AND(OR(CARI!$C$5="",ISNUMBER(SEARCH(CARI!$C$5,$B28&" "&$C28&" "&$D28&" "&$O28&" "&$I28&" "&$F28&" "&$J28&" "&$K28&" "&$L28&" "&$V28))),OR(CARI!$C$6="",$F28=CARI!$C$6),OR(CARI!$C$7="",$G28=CARI!$C$7),OR(CARI!$C$8="",$T28=CARI!$C$8)),MAX($Z$3:Z27)+1,"")) -> 25 | AA28: =IF($Y28="","",MAX($AA$3:AA27)+1) -> 25 | AB28: =IF($F28="","",$F28&"#"&COUNTIF($F$4:$F28,$F28)) -> Kp. Wangkal#6 | AC28: =IF($B28="","",IF(AND(OR(CETAK!$J$10="",$F28=CETAK!$J$10),OR(CETAK!$J$11="",$G28=CETAK!$J$11),OR(CETAK!$J$12="",$P28=CETAK!$J$12),OR(CETAK!$J$13="",$N28=CETAK!$J$13),OR(CETAK!$J$14="",$T28=CETAK!$J$14)),MAX($AC$3:AC27)+1,"")) -> 25 | AD28: =IF($B28="","",IF(AND(OR(ABSENSI!$H$10="",$F28=ABSENSI!$H$10),OR(ABSENSI!$H$11="",$G28=ABSENSI!$H$11),OR(ABSENSI!$H$12="",$P28=ABSENSI!$H$12)),MAX($AD$3:AD27)+1,"")) -> 25 | AE28: =IF($B28="","",IF(AND(OR(KARTU!$K$6="",$F28=KARTU!$K$6),OR(KARTU!$K$7="",$G28=KARTU!$K$7),OR(KARTU!$K$8="",$P28=KARTU!$K$8)),MAX($AE$3:AE27)+1,"")) -> 25
A29: =IF($B29="","",COUNTA($B$4:$B29)) -> 26 | B29: KET NALIH | F29: Kp. Wangkal | G29: 004 | H29: 006 | K29: Saiman | L29: Kadus 3 | M29: =IF($F29="","",$F29&IF($G29="",""," - RT "&$G29&IF($H29="","","/"&$H29))) -> Kp. Wangkal - RT 004/006 | N29: Anggota | R29: =IF(OR($B29="",$Q29=""),"",DATEDIF($Q29,TODAY(),"Y")) | S29: =IF($R29="","",INDEX(usia_label,MATCH($R29,usia_min,1))) | T29: Aktif | W29: asli: Ket Nalih kp wangkal RT 04/06 | X29: =IF($M29="","",$M29&"#"&COUNTIF($M$4:$M29,$M29)) -> Kp. Wangkal - RT 004/006#5 | Y29: =IF($B29="","",IF($C29="","NIK kosong",IF(LEN($C29)<>16,"NIK bukan 16 digit",IF(COUNTIF($C$4:$C$2003,$C29&"*")>1,"NIK ganda",IF(AND($D29<>"",LEN($D29)<>16),"No. KK bukan 16 digit",IF(AND($F29="",$I29=""),"Alamat kosong",IF($N29="","Jabatan kosong",IF($O29="","No. HP kosong",IF(AND($R29<>"",$R29<17),"Usia di bawah 17",""))))))))) -> NIK kosong | Z29: =IF($B29="","",IF(AND(OR(CARI!$C$5="",ISNUMBER(SEARCH(CARI!$C$5,$B29&" "&$C29&" "&$D29&" "&$O29&" "&$I29&" "&$F29&" "&$J29&" "&$K29&" "&$L29&" "&$V29))),OR(CARI!$C$6="",$F29=CARI!$C$6),OR(CARI!$C$7="",$G29=CARI!$C$7),OR(CARI!$C$8="",$T29=CARI!$C$8)),MAX($Z$3:Z28)+1,"")) -> 26 | AA29: =IF($Y29="","",MAX($AA$3:AA28)+1) -> 26 | AB29: =IF($F29="","",$F29&"#"&COUNTIF($F$4:$F29,$F29)) -> Kp. Wangkal#7 | AC29: =IF($B29="","",IF(AND(OR(CETAK!$J$10="",$F29=CETAK!$J$10),OR(CETAK!$J$11="",$G29=CETAK!$J$11),OR(CETAK!$J$12="",$P29=CETAK!$J$12),OR(CETAK!$J$13="",$N29=CETAK!$J$13),OR(CETAK!$J$14="",$T29=CETAK!$J$14)),MAX($AC$3:AC28)+1,"")) -> 26 | AD29: =IF($B29="","",IF(AND(OR(ABSENSI!$H$10="",$F29=ABSENSI!$H$10),OR(ABSENSI!$H$11="",$G29=ABSENSI!$H$11),OR(ABSENSI!$H$12="",$P29=ABSENSI!$H$12)),MAX($AD$3:AD28)+1,"")) -> 26 | AE29: =IF($B29="","",IF(AND(OR(KARTU!$K$6="",$F29=KARTU!$K$6),OR(KARTU!$K$7="",$G29=KARTU!$K$7),OR(KARTU!$K$8="",$P29=KARTU!$K$8)),MAX($AE$3:AE28)+1,"")) -> 26
A30: =IF($B30="","",COUNTA($B$4:$B30)) -> 27 | B30: FEI | G30: 004 | H30: 001 | K30: Maska | L30: Kadus 1 | M30: =IF($F30="","",$F30&IF($G30="",""," - RT "&$G30&IF($H30="","","/"&$H30))) | N30: Anggota | R30: =IF(OR($B30="",$Q30=""),"",DATEDIF($Q30,TODAY(),"Y")) | S30: =IF($R30="","",INDEX(usia_label,MATCH($R30,usia_min,1))) | T30: Aktif | W30: asli: Fei RT 004/001 | X30: =IF($M30="","",$M30&"#"&COUNTIF($M$4:$M30,$M30)) | Y30: =IF($B30="","",IF($C30="","NIK kosong",IF(LEN($C30)<>16,"NIK bukan 16 digit",IF(COUNTIF($C$4:$C$2003,$C30&"*")>1,"NIK ganda",IF(AND($D30<>"",LEN($D30)<>16),"No. KK bukan 16 digit",IF(AND($F30="",$I30=""),"Alamat kosong",IF($N30="","Jabatan kosong",IF($O30="","No. HP kosong",IF(AND($R30<>"",$R30<17),"Usia di bawah 17",""))))))))) -> NIK kosong | Z30: =IF($B30="","",IF(AND(OR(CARI!$C$5="",ISNUMBER(SEARCH(CARI!$C$5,$B30&" "&$C30&" "&$D30&" "&$O30&" "&$I30&" "&$F30&" "&$J30&" "&$K30&" "&$L30&" "&$V30))),OR(CARI!$C$6="",$F30=CARI!$C$6),OR(CARI!$C$7="",$G30=CARI!$C$7),OR(CARI!$C$8="",$T30=CARI!$C$8)),MAX($Z$3:Z29)+1,"")) -> 27 | AA30: =IF($Y30="","",MAX($AA$3:AA29)+1) -> 27 | AB30: =IF($F30="","",$F30&"#"&COUNTIF($F$4:$F30,$F30)) | AC30: =IF($B30="","",IF(AND(OR(CETAK!$J$10="",$F30=CETAK!$J$10),OR(CETAK!$J$11="",$G30=CETAK!$J$11),OR(CETAK!$J$12="",$P30=CETAK!$J$12),OR(CETAK!$J$13="",$N30=CETAK!$J$13),OR(CETAK!$J$14="",$T30=CETAK!$J$14)),MAX($AC$3:AC29)+1,"")) -> 27 | AD30: =IF($B30="","",IF(AND(OR(ABSENSI!$H$10="",$F30=ABSENSI!$H$10),OR(ABSENSI!$H$11="",$G30=ABSENSI!$H$11),OR(ABSENSI!$H$12="",$P30=ABSENSI!$H$12)),MAX($AD$3:AD29)+1,"")) -> 27 | AE30: =IF($B30="","",IF(AND(OR(KARTU!$K$6="",$F30=KARTU!$K$6),OR(KARTU!$K$7="",$G30=KARTU!$K$7),OR(KARTU!$K$8="",$P30=KARTU!$K$8)),MAX($AE$3:AE29)+1,"")) -> 27
A31: =IF($B31="","",COUNTA($B$4:$B31)) -> 28 | B31: AAL | F31: Kp. Kuda Kuda | G31: 004 | H31: 002 | J31: Onin | K31: Pasni | L31: Kadus 1 | M31: =IF($F31="","",$F31&IF($G31="",""," - RT "&$G31&IF($H31="","","/"&$H31))) -> Kp. Kuda Kuda - RT 004/002 | N31: Anggota | R31: =IF(OR($B31="",$Q31=""),"",DATEDIF($Q31,TODAY(),"Y")) | S31: =IF($R31="","",INDEX(usia_label,MATCH($R31,usia_min,1))) | T31: Aktif | W31: asli: Aal rt. 04/02 rt. Onin | X31: =IF($M31="","",$M31&"#"&COUNTIF($M$4:$M31,$M31)) -> Kp. Kuda Kuda - RT 004/002#1 | Y31: =IF($B31="","",IF($C31="","NIK kosong",IF(LEN($C31)<>16,"NIK bukan 16 digit",IF(COUNTIF($C$4:$C$2003,$C31&"*")>1,"NIK ganda",IF(AND($D31<>"",LEN($D31)<>16),"No. KK bukan 16 digit",IF(AND($F31="",$I31=""),"Alamat kosong",IF($N31="","Jabatan kosong",IF($O31="","No. HP kosong",IF(AND($R31<>"",$R31<17),"Usia di bawah 17",""))))))))) -> NIK kosong | Z31: =IF($B31="","",IF(AND(OR(CARI!$C$5="",ISNUMBER(SEARCH(CARI!$C$5,$B31&" "&$C31&" "&$D31&" "&$O31&" "&$I31&" "&$F31&" "&$J31&" "&$K31&" "&$L31&" "&$V31))),OR(CARI!$C$6="",$F31=CARI!$C$6),OR(CARI!$C$7="",$G31=CARI!$C$7),OR(CARI!$C$8="",$T31=CARI!$C$8)),MAX($Z$3:Z30)+1,"")) -> 28 | AA31: =IF($Y31="","",MAX($AA$3:AA30)+1) -> 28 | AB31: =IF($F31="","",$F31&"#"&COUNTIF($F$4:$F31,$F31)) -> Kp. Kuda Kuda#6 | AC31: =IF($B31="","",IF(AND(OR(CETAK!$J$10="",$F31=CETAK!$J$10),OR(CETAK!$J$11="",$G31=CETAK!$J$11),OR(CETAK!$J$12="",$P31=CETAK!$J$12),OR(CETAK!$J$13="",$N31=CETAK!$J$13),OR(CETAK!$J$14="",$T31=CETAK!$J$14)),MAX($AC$3:AC30)+1,"")) -> 28 | AD31: =IF($B31="","",IF(AND(OR(ABSENSI!$H$10="",$F31=ABSENSI!$H$10),OR(ABSENSI!$H$11="",$G31=ABSENSI!$H$11),OR(ABSENSI!$H$12="",$P31=ABSENSI!$H$12)),MAX($AD$3:AD30)+1,"")) -> 28 | AE31: =IF($B31="","",IF(AND(OR(KARTU!$K$6="",$F31=KARTU!$K$6),OR(KARTU!$K$7="",$G31=KARTU!$K$7),OR(KARTU!$K$8="",$P31=KARTU!$K$8)),MAX($AE$3:AE30)+1,"")) -> 28
A32: =IF($B32="","",COUNTA($B$4:$B32)) -> 29 | B32: OMAN | G32: 003 | H32: 002 | K32: Pasni | L32: Kadus 1 | M32: =IF($F32="","",$F32&IF($G32="",""," - RT "&$G32&IF($H32="","","/"&$H32))) | N32: Anggota | R32: =IF(OR($B32="",$Q32=""),"",DATEDIF($Q32,TODAY(),"Y")) | S32: =IF($R32="","",INDEX(usia_label,MATCH($R32,usia_min,1))) | T32: Aktif | W32: asli: Oman RT. 003/002 | X32: =IF($M32="","",$M32&"#"&COUNTIF($M$4:$M32,$M32)) | Y32: =IF($B32="","",IF($C32="","NIK kosong",IF(LEN($C32)<>16,"NIK bukan 16 digit",IF(COUNTIF($C$4:$C$2003,$C32&"*")>1,"NIK ganda",IF(AND($D32<>"",LEN($D32)<>16),"No. KK bukan 16 digit",IF(AND($F32="",$I32=""),"Alamat kosong",IF($N32="","Jabatan kosong",IF($O32="","No. HP kosong",IF(AND($R32<>"",$R32<17),"Usia di bawah 17",""))))))))) -> NIK kosong | Z32: =IF($B32="","",IF(AND(OR(CARI!$C$5="",ISNUMBER(SEARCH(CARI!$C$5,$B32&" "&$C32&" "&$D32&" "&$O32&" "&$I32&" "&$F32&" "&$J32&" "&$K32&" "&$L32&" "&$V32))),OR(CARI!$C$6="",$F32=CARI!$C$6),OR(CARI!$C$7="",$G32=CARI!$C$7),OR(CARI!$C$8="",$T32=CARI!$C$8)),MAX($Z$3:Z31)+1,"")) -> 29 | AA32: =IF($Y32="","",MAX($AA$3:AA31)+1) -> 29 | AB32: =IF($F32="","",$F32&"#"&COUNTIF($F$4:$F32,$F32)) | AC32: =IF($B32="","",IF(AND(OR(CETAK!$J$10="",$F32=CETAK!$J$10),OR(CETAK!$J$11="",$G32=CETAK!$J$11),OR(CETAK!$J$12="",$P32=CETAK!$J$12),OR(CETAK!$J$13="",$N32=CETAK!$J$13),OR(CETAK!$J$14="",$T32=CETAK!$J$14)),MAX($AC$3:AC31)+1,"")) -> 29 | AD32: =IF($B32="","",IF(AND(OR(ABSENSI!$H$10="",$F32=ABSENSI!$H$10),OR(ABSENSI!$H$11="",$G32=ABSENSI!$H$11),OR(ABSENSI!$H$12="",$P32=ABSENSI!$H$12)),MAX($AD$3:AD31)+1,"")) -> 29 | AE32: =IF($B32="","",IF(AND(OR(KARTU!$K$6="",$F32=KARTU!$K$6),OR(KARTU!$K$7="",$G32=KARTU!$K$7),OR(KARTU!$K$8="",$P32=KARTU!$K$8)),MAX($AE$3:AE31)+1,"")) -> 29
